11/Jun/2023 13:27:19 [Thread-1 (process_request_thread):15800] [django.request:241] [ERROR]- Internal Server Error: /shop/api/v1/customer/details
Traceback (most recent call last):
  File "E:\WorkSpace\PythonWorkSpace\shopping_platform\venv\lib\site-packages\django_redis\cache.py", line 31, in _decorator
    return method(self, *args, **kwargs)
  File "E:\WorkSpace\PythonWorkSpace\shopping_platform\venv\lib\site-packages\django_redis\cache.py", line 98, in _get
    return self.client.get(key, default=default, version=version, client=client)
  File "E:\WorkSpace\PythonWorkSpace\shopping_platform\venv\lib\site-packages\django_redis\client\default.py", line 260, in get
    raise ConnectionInterrupted(connection=client) from e
django_redis.exceptions.ConnectionInterrupted: Redis TimeoutError: Timeout connecting to server

During handling of the above exception, another exception occurred:

Traceback (most recent call last):
  File "E:\WorkSpace\PythonWorkSpace\shopping_platform\venv\lib\site-packages\django\core\handlers\exception.py", line 55, in inner
    response = get_response(request)
  File "E:\WorkSpace\PythonWorkSpace\shopping_platform\venv\lib\site-packages\django\core\handlers\base.py", line 197, in _get_response
    response = wrapped_callback(request, *callback_args, **callback_kwargs)
  File "E:\WorkSpace\PythonWorkSpace\shopping_platform\venv\lib\site-packages\django\views\decorators\csrf.py", line 56, in wrapper_view
    return view_func(*args, **kwargs)
  File "E:\WorkSpace\PythonWorkSpace\shopping_platform\venv\lib\site-packages\django\views\generic\base.py", line 104, in view
    return self.dispatch(request, *args, **kwargs)
  File "E:\WorkSpace\PythonWorkSpace\shopping_platform\venv\lib\site-packages\rest_framework\views.py", line 509, in dispatch
    response = self.handle_exception(exc)
  File "E:\WorkSpace\PythonWorkSpace\shopping_platform\venv\lib\site-packages\rest_framework\views.py", line 469, in handle_exception
    self.raise_uncaught_exception(exc)
  File "E:\WorkSpace\PythonWorkSpace\shopping_platform\venv\lib\site-packages\rest_framework\views.py", line 480, in raise_uncaught_exception
    raise exc
  File "E:\WorkSpace\PythonWorkSpace\shopping_platform\venv\lib\site-packages\rest_framework\views.py", line 506, in dispatch
    response = handler(request, *args, **kwargs)
  File "E:\WorkSpace\PythonWorkSpace\shopping_platform\customers\views.py", line 151, in get
    customer = cache.get(customer_id)
  File "E:\WorkSpace\PythonWorkSpace\shopping_platform\venv\lib\site-packages\django_redis\cache.py", line 91, in get
    value = self._get(key, default, version, client)
  File "E:\WorkSpace\PythonWorkSpace\shopping_platform\venv\lib\site-packages\django_redis\cache.py", line 38, in _decorator
    raise e.__cause__
  File "E:\WorkSpace\PythonWorkSpace\shopping_platform\venv\lib\site-packages\django_redis\client\default.py", line 258, in get
    value = client.get(key)
  File "E:\WorkSpace\PythonWorkSpace\shopping_platform\venv\lib\site-packages\redis\commands\core.py", line 1801, in get
    return self.execute_command("GET", name)
  File "E:\WorkSpace\PythonWorkSpace\shopping_platform\venv\lib\site-packages\redis\client.py", line 1266, in execute_command
    conn = self.connection or pool.get_connection(command_name, **options)
  File "E:\WorkSpace\PythonWorkSpace\shopping_platform\venv\lib\site-packages\redis\connection.py", line 1457, in get_connection
    connection.connect()
  File "E:\WorkSpace\PythonWorkSpace\shopping_platform\venv\lib\site-packages\redis\connection.py", line 703, in connect
    raise TimeoutError("Timeout connecting to server")
redis.exceptions.TimeoutError: Timeout connecting to server
11/Jun/2023 13:28:21 [Thread-1 (process_request_thread):11776] [django.request:241] [ERROR]- Internal Server Error: /shop/api/v1/customer/details
Traceback (most recent call last):
  File "E:\WorkSpace\PythonWorkSpace\shopping_platform\venv\lib\site-packages\django_redis\cache.py", line 31, in _decorator
    return method(self, *args, **kwargs)
  File "E:\WorkSpace\PythonWorkSpace\shopping_platform\venv\lib\site-packages\django_redis\cache.py", line 98, in _get
    return self.client.get(key, default=default, version=version, client=client)
  File "E:\WorkSpace\PythonWorkSpace\shopping_platform\venv\lib\site-packages\django_redis\client\default.py", line 260, in get
    raise ConnectionInterrupted(connection=client) from e
django_redis.exceptions.ConnectionInterrupted: Redis TimeoutError: Timeout connecting to server

During handling of the above exception, another exception occurred:

Traceback (most recent call last):
  File "E:\WorkSpace\PythonWorkSpace\shopping_platform\venv\lib\site-packages\django\core\handlers\exception.py", line 55, in inner
    response = get_response(request)
  File "E:\WorkSpace\PythonWorkSpace\shopping_platform\venv\lib\site-packages\django\core\handlers\base.py", line 197, in _get_response
    response = wrapped_callback(request, *callback_args, **callback_kwargs)
  File "E:\WorkSpace\PythonWorkSpace\shopping_platform\venv\lib\site-packages\django\views\decorators\csrf.py", line 56, in wrapper_view
    return view_func(*args, **kwargs)
  File "E:\WorkSpace\PythonWorkSpace\shopping_platform\venv\lib\site-packages\django\views\generic\base.py", line 104, in view
    return self.dispatch(request, *args, **kwargs)
  File "E:\WorkSpace\PythonWorkSpace\shopping_platform\venv\lib\site-packages\rest_framework\views.py", line 509, in dispatch
    response = self.handle_exception(exc)
  File "E:\WorkSpace\PythonWorkSpace\shopping_platform\venv\lib\site-packages\rest_framework\views.py", line 469, in handle_exception
    self.raise_uncaught_exception(exc)
  File "E:\WorkSpace\PythonWorkSpace\shopping_platform\venv\lib\site-packages\rest_framework\views.py", line 480, in raise_uncaught_exception
    raise exc
  File "E:\WorkSpace\PythonWorkSpace\shopping_platform\venv\lib\site-packages\rest_framework\views.py", line 506, in dispatch
    response = handler(request, *args, **kwargs)
  File "E:\WorkSpace\PythonWorkSpace\shopping_platform\customers\views.py", line 151, in get
    customer = cache.get(customer_id)
  File "E:\WorkSpace\PythonWorkSpace\shopping_platform\venv\lib\site-packages\django_redis\cache.py", line 91, in get
    value = self._get(key, default, version, client)
  File "E:\WorkSpace\PythonWorkSpace\shopping_platform\venv\lib\site-packages\django_redis\cache.py", line 38, in _decorator
    raise e.__cause__
  File "E:\WorkSpace\PythonWorkSpace\shopping_platform\venv\lib\site-packages\django_redis\client\default.py", line 258, in get
    value = client.get(key)
  File "E:\WorkSpace\PythonWorkSpace\shopping_platform\venv\lib\site-packages\redis\commands\core.py", line 1801, in get
    return self.execute_command("GET", name)
  File "E:\WorkSpace\PythonWorkSpace\shopping_platform\venv\lib\site-packages\redis\client.py", line 1266, in execute_command
    conn = self.connection or pool.get_connection(command_name, **options)
  File "E:\WorkSpace\PythonWorkSpace\shopping_platform\venv\lib\site-packages\redis\connection.py", line 1457, in get_connection
    connection.connect()
  File "E:\WorkSpace\PythonWorkSpace\shopping_platform\venv\lib\site-packages\redis\connection.py", line 703, in connect
    raise TimeoutError("Timeout connecting to server")
redis.exceptions.TimeoutError: Timeout connecting to server
11/Jun/2023 14:18:18 [Thread-1 (process_request_thread):12832] [django.request:241] [ERROR]- Internal Server Error: /shop/api/v1/customer/details
Traceback (most recent call last):
  File "E:\WorkSpace\PythonWorkSpace\shopping_platform\venv\lib\site-packages\django\core\handlers\exception.py", line 55, in inner
    response = get_response(request)
  File "E:\WorkSpace\PythonWorkSpace\shopping_platform\venv\lib\site-packages\django\core\handlers\base.py", line 197, in _get_response
    response = wrapped_callback(request, *callback_args, **callback_kwargs)
  File "E:\WorkSpace\PythonWorkSpace\shopping_platform\venv\lib\site-packages\django\views\decorators\csrf.py", line 56, in wrapper_view
    return view_func(*args, **kwargs)
  File "E:\WorkSpace\PythonWorkSpace\shopping_platform\venv\lib\site-packages\django\views\generic\base.py", line 104, in view
    return self.dispatch(request, *args, **kwargs)
  File "E:\WorkSpace\PythonWorkSpace\shopping_platform\venv\lib\site-packages\rest_framework\views.py", line 509, in dispatch
    response = self.handle_exception(exc)
  File "E:\WorkSpace\PythonWorkSpace\shopping_platform\venv\lib\site-packages\rest_framework\views.py", line 469, in handle_exception
    self.raise_uncaught_exception(exc)
  File "E:\WorkSpace\PythonWorkSpace\shopping_platform\venv\lib\site-packages\rest_framework\views.py", line 480, in raise_uncaught_exception
    raise exc
  File "E:\WorkSpace\PythonWorkSpace\shopping_platform\venv\lib\site-packages\rest_framework\views.py", line 506, in dispatch
    response = handler(request, *args, **kwargs)
  File "E:\WorkSpace\PythonWorkSpace\shopping_platform\customers\views.py", line 165, in get
    customer = Customers.objects.prefetch_related('address').get(bc_id=customer_id)
  File "E:\WorkSpace\PythonWorkSpace\shopping_platform\venv\lib\site-packages\django\db\models\query.py", line 637, in get
    raise self.model.DoesNotExist(
customers.models.Customers.DoesNotExist: Customers matching query does not exist.
11/Jun/2023 14:20:22 [Thread-1 (process_request_thread):1880] [django.request:241] [ERROR]- Internal Server Error: /shop/api/v1/customers/address/details
Traceback (most recent call last):
  File "E:\WorkSpace\PythonWorkSpace\shopping_platform\venv\lib\site-packages\django\core\handlers\exception.py", line 55, in inner
    response = get_response(request)
  File "E:\WorkSpace\PythonWorkSpace\shopping_platform\venv\lib\site-packages\django\core\handlers\base.py", line 197, in _get_response
    response = wrapped_callback(request, *callback_args, **callback_kwargs)
  File "E:\WorkSpace\PythonWorkSpace\shopping_platform\venv\lib\site-packages\django\views\decorators\csrf.py", line 56, in wrapper_view
    return view_func(*args, **kwargs)
  File "E:\WorkSpace\PythonWorkSpace\shopping_platform\venv\lib\site-packages\django\views\generic\base.py", line 104, in view
    return self.dispatch(request, *args, **kwargs)
  File "E:\WorkSpace\PythonWorkSpace\shopping_platform\venv\lib\site-packages\rest_framework\views.py", line 509, in dispatch
    response = self.handle_exception(exc)
  File "E:\WorkSpace\PythonWorkSpace\shopping_platform\venv\lib\site-packages\rest_framework\views.py", line 469, in handle_exception
    self.raise_uncaught_exception(exc)
  File "E:\WorkSpace\PythonWorkSpace\shopping_platform\venv\lib\site-packages\rest_framework\views.py", line 480, in raise_uncaught_exception
    raise exc
  File "E:\WorkSpace\PythonWorkSpace\shopping_platform\venv\lib\site-packages\rest_framework\views.py", line 506, in dispatch
    response = handler(request, *args, **kwargs)
  File "E:\WorkSpace\PythonWorkSpace\shopping_platform\addresses\views.py", line 144, in get
    cache.set(f'address:{address.address_id}', address)
AttributeError: 'QuerySet' object has no attribute 'address_id'
11/Jun/2023 14:59:07 [Thread-1 (process_request_thread):11808] [django.request:241] [ERROR]- Internal Server Error: /shop/api/v1/carts
Traceback (most recent call last):
  File "E:\WorkSpace\PythonWorkSpace\shopping_platform\venv\lib\site-packages\django\core\handlers\exception.py", line 55, in inner
    response = get_response(request)
  File "E:\WorkSpace\PythonWorkSpace\shopping_platform\venv\lib\site-packages\django\core\handlers\base.py", line 220, in _get_response
    response = response.render()
  File "E:\WorkSpace\PythonWorkSpace\shopping_platform\venv\lib\site-packages\django\template\response.py", line 114, in render
    self.content = self.rendered_content
  File "E:\WorkSpace\PythonWorkSpace\shopping_platform\venv\lib\site-packages\rest_framework\response.py", line 70, in rendered_content
    ret = renderer.render(self.data, accepted_media_type, context)
  File "E:\WorkSpace\PythonWorkSpace\shopping_platform\venv\lib\site-packages\rest_framework\renderers.py", line 99, in render
    ret = json.dumps(
  File "E:\WorkSpace\PythonWorkSpace\shopping_platform\venv\lib\site-packages\rest_framework\utils\json.py", line 25, in dumps
    return json.dumps(*args, **kwargs)
  File "E:\software\Python\lib\json\__init__.py", line 238, in dumps
    **kw).encode(obj)
  File "E:\software\Python\lib\json\encoder.py", line 199, in encode
    chunks = self.iterencode(o, _one_shot=True)
  File "E:\software\Python\lib\json\encoder.py", line 257, in iterencode
    return _iterencode(o, 0)
  File "E:\WorkSpace\PythonWorkSpace\shopping_platform\venv\lib\site-packages\rest_framework\utils\encoders.py", line 67, in default
    return super().default(obj)
  File "E:\software\Python\lib\json\encoder.py", line 179, in default
    raise TypeError(f'Object of type {o.__class__.__name__} '
TypeError: Object of type Carts is not JSON serializable
11/Jun/2023 14:59:34 [Thread-1 (process_request_thread):14580] [django.request:241] [ERROR]- Internal Server Error: /shop/api/v1/carts
Traceback (most recent call last):
  File "E:\WorkSpace\PythonWorkSpace\shopping_platform\venv\lib\site-packages\django\core\handlers\exception.py", line 55, in inner
    response = get_response(request)
  File "E:\WorkSpace\PythonWorkSpace\shopping_platform\venv\lib\site-packages\django\core\handlers\base.py", line 220, in _get_response
    response = response.render()
  File "E:\WorkSpace\PythonWorkSpace\shopping_platform\venv\lib\site-packages\django\template\response.py", line 114, in render
    self.content = self.rendered_content
  File "E:\WorkSpace\PythonWorkSpace\shopping_platform\venv\lib\site-packages\rest_framework\response.py", line 70, in rendered_content
    ret = renderer.render(self.data, accepted_media_type, context)
  File "E:\WorkSpace\PythonWorkSpace\shopping_platform\venv\lib\site-packages\rest_framework\renderers.py", line 99, in render
    ret = json.dumps(
  File "E:\WorkSpace\PythonWorkSpace\shopping_platform\venv\lib\site-packages\rest_framework\utils\json.py", line 25, in dumps
    return json.dumps(*args, **kwargs)
  File "E:\software\Python\lib\json\__init__.py", line 238, in dumps
    **kw).encode(obj)
  File "E:\software\Python\lib\json\encoder.py", line 199, in encode
    chunks = self.iterencode(o, _one_shot=True)
  File "E:\software\Python\lib\json\encoder.py", line 257, in iterencode
    return _iterencode(o, 0)
  File "E:\WorkSpace\PythonWorkSpace\shopping_platform\venv\lib\site-packages\rest_framework\utils\encoders.py", line 67, in default
    return super().default(obj)
  File "E:\software\Python\lib\json\encoder.py", line 179, in default
    raise TypeError(f'Object of type {o.__class__.__name__} '
TypeError: Object of type Carts is not JSON serializable
11/Jun/2023 15:00:58 [Thread-1 (process_request_thread):7936] [django.request:241] [ERROR]- Internal Server Error: /shop/api/v1/carts
Traceback (most recent call last):
  File "E:\WorkSpace\PythonWorkSpace\shopping_platform\venv\lib\site-packages\django\core\handlers\exception.py", line 55, in inner
    response = get_response(request)
  File "E:\WorkSpace\PythonWorkSpace\shopping_platform\venv\lib\site-packages\django\core\handlers\base.py", line 220, in _get_response
    response = response.render()
  File "E:\WorkSpace\PythonWorkSpace\shopping_platform\venv\lib\site-packages\django\template\response.py", line 114, in render
    self.content = self.rendered_content
  File "E:\WorkSpace\PythonWorkSpace\shopping_platform\venv\lib\site-packages\rest_framework\response.py", line 70, in rendered_content
    ret = renderer.render(self.data, accepted_media_type, context)
  File "E:\WorkSpace\PythonWorkSpace\shopping_platform\venv\lib\site-packages\rest_framework\renderers.py", line 99, in render
    ret = json.dumps(
  File "E:\WorkSpace\PythonWorkSpace\shopping_platform\venv\lib\site-packages\rest_framework\utils\json.py", line 25, in dumps
    return json.dumps(*args, **kwargs)
  File "E:\software\Python\lib\json\__init__.py", line 238, in dumps
    **kw).encode(obj)
  File "E:\software\Python\lib\json\encoder.py", line 199, in encode
    chunks = self.iterencode(o, _one_shot=True)
  File "E:\software\Python\lib\json\encoder.py", line 257, in iterencode
    return _iterencode(o, 0)
  File "E:\WorkSpace\PythonWorkSpace\shopping_platform\venv\lib\site-packages\rest_framework\utils\encoders.py", line 67, in default
    return super().default(obj)
  File "E:\software\Python\lib\json\encoder.py", line 179, in default
    raise TypeError(f'Object of type {o.__class__.__name__} '
TypeError: Object of type Carts is not JSON serializable
11/Jun/2023 15:01:28 [Thread-1 (process_request_thread):14328] [django.request:241] [ERROR]- Internal Server Error: /shop/api/v1/carts
Traceback (most recent call last):
  File "E:\WorkSpace\PythonWorkSpace\shopping_platform\venv\lib\site-packages\django\core\handlers\exception.py", line 55, in inner
    response = get_response(request)
  File "E:\WorkSpace\PythonWorkSpace\shopping_platform\venv\lib\site-packages\django\core\handlers\base.py", line 197, in _get_response
    response = wrapped_callback(request, *callback_args, **callback_kwargs)
  File "E:\WorkSpace\PythonWorkSpace\shopping_platform\venv\lib\site-packages\django\views\decorators\csrf.py", line 56, in wrapper_view
    return view_func(*args, **kwargs)
  File "E:\WorkSpace\PythonWorkSpace\shopping_platform\venv\lib\site-packages\django\views\generic\base.py", line 104, in view
    return self.dispatch(request, *args, **kwargs)
  File "E:\WorkSpace\PythonWorkSpace\shopping_platform\venv\lib\site-packages\rest_framework\views.py", line 509, in dispatch
    response = self.handle_exception(exc)
  File "E:\WorkSpace\PythonWorkSpace\shopping_platform\venv\lib\site-packages\rest_framework\views.py", line 469, in handle_exception
    self.raise_uncaught_exception(exc)
  File "E:\WorkSpace\PythonWorkSpace\shopping_platform\venv\lib\site-packages\rest_framework\views.py", line 480, in raise_uncaught_exception
    raise exc
  File "E:\WorkSpace\PythonWorkSpace\shopping_platform\venv\lib\site-packages\rest_framework\views.py", line 506, in dispatch
    response = handler(request, *args, **kwargs)
  File "E:\WorkSpace\PythonWorkSpace\shopping_platform\carts\views.py", line 23, in get
    'data': json.loads(cart_data)
  File "E:\software\Python\lib\json\__init__.py", line 339, in loads
    raise TypeError(f'the JSON object must be str, bytes or bytearray, '
TypeError: the JSON object must be str, bytes or bytearray, not Carts
11/Jun/2023 15:31:53 [Thread-1 (process_request_thread):316] [django.request:241] [ERROR]- Internal Server Error: /shop/api/v1/product/details
Traceback (most recent call last):
  File "E:\WorkSpace\PythonWorkSpace\shopping_platform\venv\lib\site-packages\django\core\handlers\exception.py", line 55, in inner
    response = get_response(request)
  File "E:\WorkSpace\PythonWorkSpace\shopping_platform\venv\lib\site-packages\django\core\handlers\base.py", line 197, in _get_response
    response = wrapped_callback(request, *callback_args, **callback_kwargs)
  File "E:\WorkSpace\PythonWorkSpace\shopping_platform\venv\lib\site-packages\django\views\decorators\csrf.py", line 56, in wrapper_view
    return view_func(*args, **kwargs)
  File "E:\WorkSpace\PythonWorkSpace\shopping_platform\venv\lib\site-packages\django\views\generic\base.py", line 104, in view
    return self.dispatch(request, *args, **kwargs)
  File "E:\WorkSpace\PythonWorkSpace\shopping_platform\venv\lib\site-packages\rest_framework\views.py", line 509, in dispatch
    response = self.handle_exception(exc)
  File "E:\WorkSpace\PythonWorkSpace\shopping_platform\venv\lib\site-packages\rest_framework\views.py", line 469, in handle_exception
    self.raise_uncaught_exception(exc)
  File "E:\WorkSpace\PythonWorkSpace\shopping_platform\venv\lib\site-packages\rest_framework\views.py", line 480, in raise_uncaught_exception
    raise exc
  File "E:\WorkSpace\PythonWorkSpace\shopping_platform\venv\lib\site-packages\rest_framework\views.py", line 506, in dispatch
    response = handler(request, *args, **kwargs)
  File "E:\WorkSpace\PythonWorkSpace\shopping_platform\products\views.py", line 263, in get
    product_data = ProductSerializers(product).data
  File "E:\WorkSpace\PythonWorkSpace\shopping_platform\venv\lib\site-packages\rest_framework\serializers.py", line 555, in data
    ret = super().data
  File "E:\WorkSpace\PythonWorkSpace\shopping_platform\venv\lib\site-packages\rest_framework\serializers.py", line 253, in data
    self._data = self.to_representation(self.instance)
  File "E:\WorkSpace\PythonWorkSpace\shopping_platform\venv\lib\site-packages\rest_framework\serializers.py", line 507, in to_representation
    for field in fields:
  File "E:\WorkSpace\PythonWorkSpace\shopping_platform\venv\lib\site-packages\rest_framework\serializers.py", line 368, in _readable_fields
    for field in self.fields.values():
  File "E:\WorkSpace\PythonWorkSpace\shopping_platform\venv\lib\site-packages\django\utils\functional.py", line 57, in __get__
    res = instance.__dict__[self.name] = self.func(instance)
  File "E:\WorkSpace\PythonWorkSpace\shopping_platform\venv\lib\site-packages\rest_framework\serializers.py", line 356, in fields
    for key, value in self.get_fields().items():
  File "E:\WorkSpace\PythonWorkSpace\shopping_platform\venv\lib\site-packages\rest_framework\serializers.py", line 1052, in get_fields
    field_names = self.get_field_names(declared_fields, info)
  File "E:\WorkSpace\PythonWorkSpace\shopping_platform\venv\lib\site-packages\rest_framework\serializers.py", line 1175, in get_field_names
    assert field_name in fields, (
AssertionError: The field 'created_at' was included on serializer ProductSerializers in the 'exclude' option, but does not match any model field.
11/Jun/2023 15:32:29 [Thread-1 (process_request_thread):10588] [django.request:241] [ERROR]- Internal Server Error: /shop/api/v1/product/details
Traceback (most recent call last):
  File "E:\WorkSpace\PythonWorkSpace\shopping_platform\venv\lib\site-packages\rest_framework\fields.py", line 446, in get_attribute
    return get_attribute(instance, self.source_attrs)
  File "E:\WorkSpace\PythonWorkSpace\shopping_platform\venv\lib\site-packages\rest_framework\fields.py", line 96, in get_attribute
    instance = getattr(instance, attr)
AttributeError: 'QuerySet' object has no attribute 'name'

During handling of the above exception, another exception occurred:

Traceback (most recent call last):
  File "E:\WorkSpace\PythonWorkSpace\shopping_platform\venv\lib\site-packages\django\core\handlers\exception.py", line 55, in inner
    response = get_response(request)
  File "E:\WorkSpace\PythonWorkSpace\shopping_platform\venv\lib\site-packages\django\core\handlers\base.py", line 197, in _get_response
    response = wrapped_callback(request, *callback_args, **callback_kwargs)
  File "E:\WorkSpace\PythonWorkSpace\shopping_platform\venv\lib\site-packages\django\views\decorators\csrf.py", line 56, in wrapper_view
    return view_func(*args, **kwargs)
  File "E:\WorkSpace\PythonWorkSpace\shopping_platform\venv\lib\site-packages\django\views\generic\base.py", line 104, in view
    return self.dispatch(request, *args, **kwargs)
  File "E:\WorkSpace\PythonWorkSpace\shopping_platform\venv\lib\site-packages\rest_framework\views.py", line 509, in dispatch
    response = self.handle_exception(exc)
  File "E:\WorkSpace\PythonWorkSpace\shopping_platform\venv\lib\site-packages\rest_framework\views.py", line 469, in handle_exception
    self.raise_uncaught_exception(exc)
  File "E:\WorkSpace\PythonWorkSpace\shopping_platform\venv\lib\site-packages\rest_framework\views.py", line 480, in raise_uncaught_exception
    raise exc
  File "E:\WorkSpace\PythonWorkSpace\shopping_platform\venv\lib\site-packages\rest_framework\views.py", line 506, in dispatch
    response = handler(request, *args, **kwargs)
  File "E:\WorkSpace\PythonWorkSpace\shopping_platform\products\views.py", line 263, in get
    product_data = ProductSerializers(product).data
  File "E:\WorkSpace\PythonWorkSpace\shopping_platform\venv\lib\site-packages\rest_framework\serializers.py", line 555, in data
    ret = super().data
  File "E:\WorkSpace\PythonWorkSpace\shopping_platform\venv\lib\site-packages\rest_framework\serializers.py", line 253, in data
    self._data = self.to_representation(self.instance)
  File "E:\WorkSpace\PythonWorkSpace\shopping_platform\venv\lib\site-packages\rest_framework\serializers.py", line 509, in to_representation
    attribute = field.get_attribute(instance)
  File "E:\WorkSpace\PythonWorkSpace\shopping_platform\venv\lib\site-packages\rest_framework\fields.py", line 479, in get_attribute
    raise type(exc)(msg)
AttributeError: Got AttributeError when attempting to get a value for field `name` on serializer `ProductSerializers`.
The serializer field might be named incorrectly and not match any attribute or key on the `QuerySet` instance.
Original exception text was: 'QuerySet' object has no attribute 'name'.
11/Jun/2023 16:09:44 [Thread-1 (process_request_thread):16744] [django.request:241] [ERROR]- Internal Server Error: /shop/api/v1/orders/141
Traceback (most recent call last):
  File "E:\WorkSpace\PythonWorkSpace\shopping_platform\venv\lib\site-packages\django\core\handlers\exception.py", line 55, in inner
    response = get_response(request)
  File "E:\WorkSpace\PythonWorkSpace\shopping_platform\venv\lib\site-packages\django\core\handlers\base.py", line 197, in _get_response
    response = wrapped_callback(request, *callback_args, **callback_kwargs)
  File "E:\WorkSpace\PythonWorkSpace\shopping_platform\venv\lib\site-packages\django\views\decorators\csrf.py", line 56, in wrapper_view
    return view_func(*args, **kwargs)
  File "E:\WorkSpace\PythonWorkSpace\shopping_platform\venv\lib\site-packages\django\views\generic\base.py", line 104, in view
    return self.dispatch(request, *args, **kwargs)
  File "E:\WorkSpace\PythonWorkSpace\shopping_platform\venv\lib\site-packages\rest_framework\views.py", line 509, in dispatch
    response = self.handle_exception(exc)
  File "E:\WorkSpace\PythonWorkSpace\shopping_platform\venv\lib\site-packages\rest_framework\views.py", line 469, in handle_exception
    self.raise_uncaught_exception(exc)
  File "E:\WorkSpace\PythonWorkSpace\shopping_platform\venv\lib\site-packages\rest_framework\views.py", line 480, in raise_uncaught_exception
    raise exc
  File "E:\WorkSpace\PythonWorkSpace\shopping_platform\venv\lib\site-packages\rest_framework\views.py", line 506, in dispatch
    response = handler(request, *args, **kwargs)
  File "E:\WorkSpace\PythonWorkSpace\shopping_platform\orders\views.py", line 132, in get
    order = Orders.objects.filer(bc_order_id=order_id)
AttributeError: 'Manager' object has no attribute 'filer'
11/Jun/2023 16:10:13 [Thread-1 (process_request_thread):15844] [django.request:241] [ERROR]- Internal Server Error: /shop/api/v1/orders/141
Traceback (most recent call last):
  File "E:\WorkSpace\PythonWorkSpace\shopping_platform\venv\lib\site-packages\rest_framework\fields.py", line 446, in get_attribute
    return get_attribute(instance, self.source_attrs)
  File "E:\WorkSpace\PythonWorkSpace\shopping_platform\venv\lib\site-packages\rest_framework\fields.py", line 96, in get_attribute
    instance = getattr(instance, attr)
AttributeError: 'RelatedManager' object has no attribute 'order'

During handling of the above exception, another exception occurred:

Traceback (most recent call last):
  File "E:\WorkSpace\PythonWorkSpace\shopping_platform\venv\lib\site-packages\django\core\handlers\exception.py", line 55, in inner
    response = get_response(request)
  File "E:\WorkSpace\PythonWorkSpace\shopping_platform\venv\lib\site-packages\django\core\handlers\base.py", line 197, in _get_response
    response = wrapped_callback(request, *callback_args, **callback_kwargs)
  File "E:\WorkSpace\PythonWorkSpace\shopping_platform\venv\lib\site-packages\django\views\decorators\csrf.py", line 56, in wrapper_view
    return view_func(*args, **kwargs)
  File "E:\WorkSpace\PythonWorkSpace\shopping_platform\venv\lib\site-packages\django\views\generic\base.py", line 104, in view
    return self.dispatch(request, *args, **kwargs)
  File "E:\WorkSpace\PythonWorkSpace\shopping_platform\venv\lib\site-packages\rest_framework\views.py", line 509, in dispatch
    response = self.handle_exception(exc)
  File "E:\WorkSpace\PythonWorkSpace\shopping_platform\venv\lib\site-packages\rest_framework\views.py", line 469, in handle_exception
    self.raise_uncaught_exception(exc)
  File "E:\WorkSpace\PythonWorkSpace\shopping_platform\venv\lib\site-packages\rest_framework\views.py", line 480, in raise_uncaught_exception
    raise exc
  File "E:\WorkSpace\PythonWorkSpace\shopping_platform\venv\lib\site-packages\rest_framework\views.py", line 506, in dispatch
    response = handler(request, *args, **kwargs)
  File "E:\WorkSpace\PythonWorkSpace\shopping_platform\orders\views.py", line 133, in get
    order_data = OrderSerializers(order).data
  File "E:\WorkSpace\PythonWorkSpace\shopping_platform\venv\lib\site-packages\rest_framework\serializers.py", line 555, in data
    ret = super().data
  File "E:\WorkSpace\PythonWorkSpace\shopping_platform\venv\lib\site-packages\rest_framework\serializers.py", line 253, in data
    self._data = self.to_representation(self.instance)
  File "E:\WorkSpace\PythonWorkSpace\shopping_platform\venv\lib\site-packages\rest_framework\serializers.py", line 522, in to_representation
    ret[field.field_name] = field.to_representation(attribute)
  File "E:\WorkSpace\PythonWorkSpace\shopping_platform\venv\lib\site-packages\rest_framework\serializers.py", line 509, in to_representation
    attribute = field.get_attribute(instance)
  File "E:\WorkSpace\PythonWorkSpace\shopping_platform\venv\lib\site-packages\rest_framework\relations.py", line 190, in get_attribute
    return super().get_attribute(instance)
  File "E:\WorkSpace\PythonWorkSpace\shopping_platform\venv\lib\site-packages\rest_framework\fields.py", line 479, in get_attribute
    raise type(exc)(msg)
AttributeError: Got AttributeError when attempting to get a value for field `order` on serializer `OrderItemSerializers`.
The serializer field might be named incorrectly and not match any attribute or key on the `RelatedManager` instance.
Original exception text was: 'RelatedManager' object has no attribute 'order'.
11/Jun/2023 16:11:01 [Thread-1 (process_request_thread):15468] [django.request:241] [ERROR]- Internal Server Error: /shop/api/v1/orders/141
Traceback (most recent call last):
  File "E:\WorkSpace\PythonWorkSpace\shopping_platform\venv\lib\site-packages\rest_framework\fields.py", line 446, in get_attribute
    return get_attribute(instance, self.source_attrs)
  File "E:\WorkSpace\PythonWorkSpace\shopping_platform\venv\lib\site-packages\rest_framework\fields.py", line 96, in get_attribute
    instance = getattr(instance, attr)
AttributeError: 'RelatedManager' object has no attribute 'product'

During handling of the above exception, another exception occurred:

Traceback (most recent call last):
  File "E:\WorkSpace\PythonWorkSpace\shopping_platform\venv\lib\site-packages\django\core\handlers\exception.py", line 55, in inner
    response = get_response(request)
  File "E:\WorkSpace\PythonWorkSpace\shopping_platform\venv\lib\site-packages\django\core\handlers\base.py", line 197, in _get_response
    response = wrapped_callback(request, *callback_args, **callback_kwargs)
  File "E:\WorkSpace\PythonWorkSpace\shopping_platform\venv\lib\site-packages\django\views\decorators\csrf.py", line 56, in wrapper_view
    return view_func(*args, **kwargs)
  File "E:\WorkSpace\PythonWorkSpace\shopping_platform\venv\lib\site-packages\django\views\generic\base.py", line 104, in view
    return self.dispatch(request, *args, **kwargs)
  File "E:\WorkSpace\PythonWorkSpace\shopping_platform\venv\lib\site-packages\rest_framework\views.py", line 509, in dispatch
    response = self.handle_exception(exc)
  File "E:\WorkSpace\PythonWorkSpace\shopping_platform\venv\lib\site-packages\rest_framework\views.py", line 469, in handle_exception
    self.raise_uncaught_exception(exc)
  File "E:\WorkSpace\PythonWorkSpace\shopping_platform\venv\lib\site-packages\rest_framework\views.py", line 480, in raise_uncaught_exception
    raise exc
  File "E:\WorkSpace\PythonWorkSpace\shopping_platform\venv\lib\site-packages\rest_framework\views.py", line 506, in dispatch
    response = handler(request, *args, **kwargs)
  File "E:\WorkSpace\PythonWorkSpace\shopping_platform\orders\views.py", line 133, in get
    order_data = OrderSerializers(order).data
  File "E:\WorkSpace\PythonWorkSpace\shopping_platform\venv\lib\site-packages\rest_framework\serializers.py", line 555, in data
    ret = super().data
  File "E:\WorkSpace\PythonWorkSpace\shopping_platform\venv\lib\site-packages\rest_framework\serializers.py", line 253, in data
    self._data = self.to_representation(self.instance)
  File "E:\WorkSpace\PythonWorkSpace\shopping_platform\venv\lib\site-packages\rest_framework\serializers.py", line 522, in to_representation
    ret[field.field_name] = field.to_representation(attribute)
  File "E:\WorkSpace\PythonWorkSpace\shopping_platform\venv\lib\site-packages\rest_framework\serializers.py", line 509, in to_representation
    attribute = field.get_attribute(instance)
  File "E:\WorkSpace\PythonWorkSpace\shopping_platform\venv\lib\site-packages\rest_framework\relations.py", line 190, in get_attribute
    return super().get_attribute(instance)
  File "E:\WorkSpace\PythonWorkSpace\shopping_platform\venv\lib\site-packages\rest_framework\fields.py", line 479, in get_attribute
    raise type(exc)(msg)
AttributeError: Got AttributeError when attempting to get a value for field `product` on serializer `OrderItemSerializers`.
The serializer field might be named incorrectly and not match any attribute or key on the `RelatedManager` instance.
Original exception text was: 'RelatedManager' object has no attribute 'product'.
11/Jun/2023 16:14:17 [Thread-1 (process_request_thread):17132] [django.request:241] [ERROR]- Internal Server Error: /shop/api/v1/orders/141
Traceback (most recent call last):
  File "E:\WorkSpace\PythonWorkSpace\shopping_platform\venv\lib\site-packages\rest_framework\fields.py", line 446, in get_attribute
    return get_attribute(instance, self.source_attrs)
  File "E:\WorkSpace\PythonWorkSpace\shopping_platform\venv\lib\site-packages\rest_framework\fields.py", line 96, in get_attribute
    instance = getattr(instance, attr)
AttributeError: 'QuerySet' object has no attribute 'order'

During handling of the above exception, another exception occurred:

Traceback (most recent call last):
  File "E:\WorkSpace\PythonWorkSpace\shopping_platform\venv\lib\site-packages\django\core\handlers\exception.py", line 55, in inner
    response = get_response(request)
  File "E:\WorkSpace\PythonWorkSpace\shopping_platform\venv\lib\site-packages\django\core\handlers\base.py", line 197, in _get_response
    response = wrapped_callback(request, *callback_args, **callback_kwargs)
  File "E:\WorkSpace\PythonWorkSpace\shopping_platform\venv\lib\site-packages\django\views\decorators\csrf.py", line 56, in wrapper_view
    return view_func(*args, **kwargs)
  File "E:\WorkSpace\PythonWorkSpace\shopping_platform\venv\lib\site-packages\django\views\generic\base.py", line 104, in view
    return self.dispatch(request, *args, **kwargs)
  File "E:\WorkSpace\PythonWorkSpace\shopping_platform\venv\lib\site-packages\rest_framework\views.py", line 509, in dispatch
    response = self.handle_exception(exc)
  File "E:\WorkSpace\PythonWorkSpace\shopping_platform\venv\lib\site-packages\rest_framework\views.py", line 469, in handle_exception
    self.raise_uncaught_exception(exc)
  File "E:\WorkSpace\PythonWorkSpace\shopping_platform\venv\lib\site-packages\rest_framework\views.py", line 480, in raise_uncaught_exception
    raise exc
  File "E:\WorkSpace\PythonWorkSpace\shopping_platform\venv\lib\site-packages\rest_framework\views.py", line 506, in dispatch
    response = handler(request, *args, **kwargs)
  File "E:\WorkSpace\PythonWorkSpace\shopping_platform\orders\views.py", line 133, in get
    order_data = OrderSerializers(order).data
  File "E:\WorkSpace\PythonWorkSpace\shopping_platform\venv\lib\site-packages\rest_framework\serializers.py", line 555, in data
    ret = super().data
  File "E:\WorkSpace\PythonWorkSpace\shopping_platform\venv\lib\site-packages\rest_framework\serializers.py", line 253, in data
    self._data = self.to_representation(self.instance)
  File "E:\WorkSpace\PythonWorkSpace\shopping_platform\venv\lib\site-packages\rest_framework\serializers.py", line 522, in to_representation
    ret[field.field_name] = field.to_representation(attribute)
  File "E:\WorkSpace\PythonWorkSpace\shopping_platform\venv\lib\site-packages\rest_framework\fields.py", line 1838, in to_representation
    return method(value)
  File "E:\WorkSpace\PythonWorkSpace\shopping_platform\orders\seriliazers.py", line 22, in get_items
    order_data = OrderItemSerializers(order_items).data
  File "E:\WorkSpace\PythonWorkSpace\shopping_platform\venv\lib\site-packages\rest_framework\serializers.py", line 555, in data
    ret = super().data
  File "E:\WorkSpace\PythonWorkSpace\shopping_platform\venv\lib\site-packages\rest_framework\serializers.py", line 253, in data
    self._data = self.to_representation(self.instance)
  File "E:\WorkSpace\PythonWorkSpace\shopping_platform\venv\lib\site-packages\rest_framework\serializers.py", line 509, in to_representation
    attribute = field.get_attribute(instance)
  File "E:\WorkSpace\PythonWorkSpace\shopping_platform\venv\lib\site-packages\rest_framework\relations.py", line 190, in get_attribute
    return super().get_attribute(instance)
  File "E:\WorkSpace\PythonWorkSpace\shopping_platform\venv\lib\site-packages\rest_framework\fields.py", line 479, in get_attribute
    raise type(exc)(msg)
AttributeError: Got AttributeError when attempting to get a value for field `order` on serializer `OrderItemSerializers`.
The serializer field might be named incorrectly and not match any attribute or key on the `QuerySet` instance.
Original exception text was: 'QuerySet' object has no attribute 'order'.
11/Jun/2023 16:15:47 [Thread-1 (process_request_thread):14468] [django.request:241] [ERROR]- Internal Server Error: /shop/api/v1/orders/141
Traceback (most recent call last):
  File "E:\WorkSpace\PythonWorkSpace\shopping_platform\venv\lib\site-packages\rest_framework\fields.py", line 446, in get_attribute
    return get_attribute(instance, self.source_attrs)
  File "E:\WorkSpace\PythonWorkSpace\shopping_platform\venv\lib\site-packages\rest_framework\fields.py", line 96, in get_attribute
    instance = getattr(instance, attr)
AttributeError: 'QuerySet' object has no attribute 'order'

During handling of the above exception, another exception occurred:

Traceback (most recent call last):
  File "E:\WorkSpace\PythonWorkSpace\shopping_platform\venv\lib\site-packages\django\core\handlers\exception.py", line 55, in inner
    response = get_response(request)
  File "E:\WorkSpace\PythonWorkSpace\shopping_platform\venv\lib\site-packages\django\core\handlers\base.py", line 197, in _get_response
    response = wrapped_callback(request, *callback_args, **callback_kwargs)
  File "E:\WorkSpace\PythonWorkSpace\shopping_platform\venv\lib\site-packages\django\views\decorators\csrf.py", line 56, in wrapper_view
    return view_func(*args, **kwargs)
  File "E:\WorkSpace\PythonWorkSpace\shopping_platform\venv\lib\site-packages\django\views\generic\base.py", line 104, in view
    return self.dispatch(request, *args, **kwargs)
  File "E:\WorkSpace\PythonWorkSpace\shopping_platform\venv\lib\site-packages\rest_framework\views.py", line 509, in dispatch
    response = self.handle_exception(exc)
  File "E:\WorkSpace\PythonWorkSpace\shopping_platform\venv\lib\site-packages\rest_framework\views.py", line 469, in handle_exception
    self.raise_uncaught_exception(exc)
  File "E:\WorkSpace\PythonWorkSpace\shopping_platform\venv\lib\site-packages\rest_framework\views.py", line 480, in raise_uncaught_exception
    raise exc
  File "E:\WorkSpace\PythonWorkSpace\shopping_platform\venv\lib\site-packages\rest_framework\views.py", line 506, in dispatch
    response = handler(request, *args, **kwargs)
  File "E:\WorkSpace\PythonWorkSpace\shopping_platform\orders\views.py", line 133, in get
    order_data = OrderSerializers(order).data
  File "E:\WorkSpace\PythonWorkSpace\shopping_platform\venv\lib\site-packages\rest_framework\serializers.py", line 555, in data
    ret = super().data
  File "E:\WorkSpace\PythonWorkSpace\shopping_platform\venv\lib\site-packages\rest_framework\serializers.py", line 253, in data
    self._data = self.to_representation(self.instance)
  File "E:\WorkSpace\PythonWorkSpace\shopping_platform\venv\lib\site-packages\rest_framework\serializers.py", line 522, in to_representation
    ret[field.field_name] = field.to_representation(attribute)
  File "E:\WorkSpace\PythonWorkSpace\shopping_platform\venv\lib\site-packages\rest_framework\fields.py", line 1838, in to_representation
    return method(value)
  File "E:\WorkSpace\PythonWorkSpace\shopping_platform\orders\seriliazers.py", line 22, in get_items
    order_data = OrderItemSerializers(order_items).data
  File "E:\WorkSpace\PythonWorkSpace\shopping_platform\venv\lib\site-packages\rest_framework\serializers.py", line 555, in data
    ret = super().data
  File "E:\WorkSpace\PythonWorkSpace\shopping_platform\venv\lib\site-packages\rest_framework\serializers.py", line 253, in data
    self._data = self.to_representation(self.instance)
  File "E:\WorkSpace\PythonWorkSpace\shopping_platform\venv\lib\site-packages\rest_framework\serializers.py", line 509, in to_representation
    attribute = field.get_attribute(instance)
  File "E:\WorkSpace\PythonWorkSpace\shopping_platform\venv\lib\site-packages\rest_framework\relations.py", line 190, in get_attribute
    return super().get_attribute(instance)
  File "E:\WorkSpace\PythonWorkSpace\shopping_platform\venv\lib\site-packages\rest_framework\fields.py", line 479, in get_attribute
    raise type(exc)(msg)
AttributeError: Got AttributeError when attempting to get a value for field `order` on serializer `OrderItemSerializers`.
The serializer field might be named incorrectly and not match any attribute or key on the `QuerySet` instance.
Original exception text was: 'QuerySet' object has no attribute 'order'.
11/Jun/2023 16:15:56 [Thread-1 (process_request_thread):3832] [django.request:241] [ERROR]- Internal Server Error: /shop/api/v1/orders/141
Traceback (most recent call last):
  File "E:\WorkSpace\PythonWorkSpace\shopping_platform\venv\lib\site-packages\rest_framework\fields.py", line 446, in get_attribute
    return get_attribute(instance, self.source_attrs)
  File "E:\WorkSpace\PythonWorkSpace\shopping_platform\venv\lib\site-packages\rest_framework\fields.py", line 96, in get_attribute
    instance = getattr(instance, attr)
AttributeError: 'QuerySet' object has no attribute 'order'

During handling of the above exception, another exception occurred:

Traceback (most recent call last):
  File "E:\WorkSpace\PythonWorkSpace\shopping_platform\venv\lib\site-packages\django\core\handlers\exception.py", line 55, in inner
    response = get_response(request)
  File "E:\WorkSpace\PythonWorkSpace\shopping_platform\venv\lib\site-packages\django\core\handlers\base.py", line 197, in _get_response
    response = wrapped_callback(request, *callback_args, **callback_kwargs)
  File "E:\WorkSpace\PythonWorkSpace\shopping_platform\venv\lib\site-packages\django\views\decorators\csrf.py", line 56, in wrapper_view
    return view_func(*args, **kwargs)
  File "E:\WorkSpace\PythonWorkSpace\shopping_platform\venv\lib\site-packages\django\views\generic\base.py", line 104, in view
    return self.dispatch(request, *args, **kwargs)
  File "E:\WorkSpace\PythonWorkSpace\shopping_platform\venv\lib\site-packages\rest_framework\views.py", line 509, in dispatch
    response = self.handle_exception(exc)
  File "E:\WorkSpace\PythonWorkSpace\shopping_platform\venv\lib\site-packages\rest_framework\views.py", line 469, in handle_exception
    self.raise_uncaught_exception(exc)
  File "E:\WorkSpace\PythonWorkSpace\shopping_platform\venv\lib\site-packages\rest_framework\views.py", line 480, in raise_uncaught_exception
    raise exc
  File "E:\WorkSpace\PythonWorkSpace\shopping_platform\venv\lib\site-packages\rest_framework\views.py", line 506, in dispatch
    response = handler(request, *args, **kwargs)
  File "E:\WorkSpace\PythonWorkSpace\shopping_platform\orders\views.py", line 133, in get
    order_data = OrderSerializers(order).data
  File "E:\WorkSpace\PythonWorkSpace\shopping_platform\venv\lib\site-packages\rest_framework\serializers.py", line 555, in data
    ret = super().data
  File "E:\WorkSpace\PythonWorkSpace\shopping_platform\venv\lib\site-packages\rest_framework\serializers.py", line 253, in data
    self._data = self.to_representation(self.instance)
  File "E:\WorkSpace\PythonWorkSpace\shopping_platform\venv\lib\site-packages\rest_framework\serializers.py", line 522, in to_representation
    ret[field.field_name] = field.to_representation(attribute)
  File "E:\WorkSpace\PythonWorkSpace\shopping_platform\venv\lib\site-packages\rest_framework\fields.py", line 1838, in to_representation
    return method(value)
  File "E:\WorkSpace\PythonWorkSpace\shopping_platform\orders\seriliazers.py", line 22, in get_items
    order_data = OrderItemSerializers(order_items).data
  File "E:\WorkSpace\PythonWorkSpace\shopping_platform\venv\lib\site-packages\rest_framework\serializers.py", line 555, in data
    ret = super().data
  File "E:\WorkSpace\PythonWorkSpace\shopping_platform\venv\lib\site-packages\rest_framework\serializers.py", line 253, in data
    self._data = self.to_representation(self.instance)
  File "E:\WorkSpace\PythonWorkSpace\shopping_platform\venv\lib\site-packages\rest_framework\serializers.py", line 509, in to_representation
    attribute = field.get_attribute(instance)
  File "E:\WorkSpace\PythonWorkSpace\shopping_platform\venv\lib\site-packages\rest_framework\relations.py", line 190, in get_attribute
    return super().get_attribute(instance)
  File "E:\WorkSpace\PythonWorkSpace\shopping_platform\venv\lib\site-packages\rest_framework\fields.py", line 479, in get_attribute
    raise type(exc)(msg)
AttributeError: Got AttributeError when attempting to get a value for field `order` on serializer `OrderItemSerializers`.
The serializer field might be named incorrectly and not match any attribute or key on the `QuerySet` instance.
Original exception text was: 'QuerySet' object has no attribute 'order'.
