31/May/2023 17:10:00 [Thread-5 (process_request_thread):10624] [django.request:241] [ERROR]- Internal Server Error: /shop/api/v1/categories/
urllib3.exceptions.SSLError: EOF occurred in violation of protocol (_ssl.c:997)

The above exception was the direct cause of the following exception:

Traceback (most recent call last):
  File "E:\WorkSpace\PythonWorkSpace\shopping_platform\venv\lib\site-packages\requests\adapters.py", line 486, in send
    resp = conn.urlopen(
  File "E:\WorkSpace\PythonWorkSpace\shopping_platform\venv\lib\site-packages\urllib3\connectionpool.py", line 844, in urlopen
    retries = retries.increment(
  File "E:\WorkSpace\PythonWorkSpace\shopping_platform\venv\lib\site-packages\urllib3\util\retry.py", line 515, in increment
    raise MaxRetryError(_pool, url, reason) from reason  # type: ignore[arg-type]
urllib3.exceptions.MaxRetryError: HTTPSConnectionPool(host='api.bigcommerce.com', port=443): Max retries exceeded with url: /stores/rmz2xgu42d/v3/catalog/categories/28 (Caused by SSLError(SSLEOFError(8, 'EOF occurred in violation of protocol (_ssl.c:997)')))

During handling of the above exception, another exception occurred:

Traceback (most recent call last):
  File "E:\WorkSpace\PythonWorkSpace\shopping_platform\venv\lib\site-packages\django\core\handlers\exception.py", line 55, in inner
    response = get_response(request)
  File "E:\WorkSpace\PythonWorkSpace\shopping_platform\venv\lib\site-packages\django\core\handlers\base.py", line 197, in _get_response
    response = wrapped_callback(request, *callback_args, **callback_kwargs)
  File "E:\WorkSpace\PythonWorkSpace\shopping_platform\venv\lib\site-packages\django\views\decorators\csrf.py", line 56, in wrapper_view
    return view_func(*args, **kwargs)
  File "E:\WorkSpace\PythonWorkSpace\shopping_platform\venv\lib\site-packages\django\views\generic\base.py", line 104, in view
    return self.dispatch(request, *args, **kwargs)
  File "E:\WorkSpace\PythonWorkSpace\shopping_platform\venv\lib\site-packages\rest_framework\views.py", line 509, in dispatch
    response = self.handle_exception(exc)
  File "E:\WorkSpace\PythonWorkSpace\shopping_platform\venv\lib\site-packages\rest_framework\views.py", line 469, in handle_exception
    self.raise_uncaught_exception(exc)
  File "E:\WorkSpace\PythonWorkSpace\shopping_platform\venv\lib\site-packages\rest_framework\views.py", line 480, in raise_uncaught_exception
    raise exc
  File "E:\WorkSpace\PythonWorkSpace\shopping_platform\venv\lib\site-packages\rest_framework\views.py", line 506, in dispatch
    response = handler(request, *args, **kwargs)
  File "E:\WorkSpace\PythonWorkSpace\shopping_platform\products\views.py", line 93, in put
    result = requests.put(url=url, headers=headers)
  File "E:\WorkSpace\PythonWorkSpace\shopping_platform\venv\lib\site-packages\requests\api.py", line 130, in put
    return request("put", url, data=data, **kwargs)
  File "E:\WorkSpace\PythonWorkSpace\shopping_platform\venv\lib\site-packages\requests\api.py", line 59, in request
    return session.request(method=method, url=url, **kwargs)
  File "E:\WorkSpace\PythonWorkSpace\shopping_platform\venv\lib\site-packages\requests\sessions.py", line 589, in request
    resp = self.send(prep, **send_kwargs)
  File "E:\WorkSpace\PythonWorkSpace\shopping_platform\venv\lib\site-packages\requests\sessions.py", line 703, in send
    r = adapter.send(request, **kwargs)
  File "E:\WorkSpace\PythonWorkSpace\shopping_platform\venv\lib\site-packages\requests\adapters.py", line 517, in send
    raise SSLError(e, request=request)
requests.exceptions.SSLError: HTTPSConnectionPool(host='api.bigcommerce.com', port=443): Max retries exceeded with url: /stores/rmz2xgu42d/v3/catalog/categories/28 (Caused by SSLError(SSLEOFError(8, 'EOF occurred in violation of protocol (_ssl.c:997)')))
31/May/2023 17:21:25 [Thread-1 (process_request_thread):17140] [django.request:241] [ERROR]- Internal Server Error: /shop/api/v1/categories/
Traceback (most recent call last):
  File "E:\WorkSpace\PythonWorkSpace\shopping_platform\venv\lib\site-packages\urllib3\connectionpool.py", line 776, in urlopen
    self._prepare_proxy(conn)
  File "E:\WorkSpace\PythonWorkSpace\shopping_platform\venv\lib\site-packages\urllib3\connectionpool.py", line 1041, in _prepare_proxy
    conn.connect()
  File "E:\WorkSpace\PythonWorkSpace\shopping_platform\venv\lib\site-packages\urllib3\connection.py", line 635, in connect
    sock_and_verified = _ssl_wrap_socket_and_match_hostname(
  File "E:\WorkSpace\PythonWorkSpace\shopping_platform\venv\lib\site-packages\urllib3\connection.py", line 774, in _ssl_wrap_socket_and_match_hostname
    ssl_sock = ssl_wrap_socket(
  File "E:\WorkSpace\PythonWorkSpace\shopping_platform\venv\lib\site-packages\urllib3\util\ssl_.py", line 459, in ssl_wrap_socket
    ssl_sock = _ssl_wrap_socket_impl(sock, context, tls_in_tls, server_hostname)
  File "E:\WorkSpace\PythonWorkSpace\shopping_platform\venv\lib\site-packages\urllib3\util\ssl_.py", line 503, in _ssl_wrap_socket_impl
    return ssl_context.wrap_socket(sock, server_hostname=server_hostname)
  File "E:\software\Python\lib\ssl.py", line 513, in wrap_socket
    return self.sslsocket_class._create(
  File "E:\software\Python\lib\ssl.py", line 1071, in _create
    self.do_handshake()
  File "E:\software\Python\lib\ssl.py", line 1342, in do_handshake
    self._sslobj.do_handshake()
ConnectionResetError: [WinError 10054] 远程主机强迫关闭了一个现有的连接。

During handling of the above exception, another exception occurred:

Traceback (most recent call last):
  File "E:\WorkSpace\PythonWorkSpace\shopping_platform\venv\lib\site-packages\requests\adapters.py", line 486, in send
    resp = conn.urlopen(
  File "E:\WorkSpace\PythonWorkSpace\shopping_platform\venv\lib\site-packages\urllib3\connectionpool.py", line 844, in urlopen
    retries = retries.increment(
  File "E:\WorkSpace\PythonWorkSpace\shopping_platform\venv\lib\site-packages\urllib3\util\retry.py", line 470, in increment
    raise reraise(type(error), error, _stacktrace)
  File "E:\WorkSpace\PythonWorkSpace\shopping_platform\venv\lib\site-packages\urllib3\util\util.py", line 38, in reraise
    raise value.with_traceback(tb)
  File "E:\WorkSpace\PythonWorkSpace\shopping_platform\venv\lib\site-packages\urllib3\connectionpool.py", line 776, in urlopen
    self._prepare_proxy(conn)
  File "E:\WorkSpace\PythonWorkSpace\shopping_platform\venv\lib\site-packages\urllib3\connectionpool.py", line 1041, in _prepare_proxy
    conn.connect()
  File "E:\WorkSpace\PythonWorkSpace\shopping_platform\venv\lib\site-packages\urllib3\connection.py", line 635, in connect
    sock_and_verified = _ssl_wrap_socket_and_match_hostname(
  File "E:\WorkSpace\PythonWorkSpace\shopping_platform\venv\lib\site-packages\urllib3\connection.py", line 774, in _ssl_wrap_socket_and_match_hostname
    ssl_sock = ssl_wrap_socket(
  File "E:\WorkSpace\PythonWorkSpace\shopping_platform\venv\lib\site-packages\urllib3\util\ssl_.py", line 459, in ssl_wrap_socket
    ssl_sock = _ssl_wrap_socket_impl(sock, context, tls_in_tls, server_hostname)
  File "E:\WorkSpace\PythonWorkSpace\shopping_platform\venv\lib\site-packages\urllib3\util\ssl_.py", line 503, in _ssl_wrap_socket_impl
    return ssl_context.wrap_socket(sock, server_hostname=server_hostname)
  File "E:\software\Python\lib\ssl.py", line 513, in wrap_socket
    return self.sslsocket_class._create(
  File "E:\software\Python\lib\ssl.py", line 1071, in _create
    self.do_handshake()
  File "E:\software\Python\lib\ssl.py", line 1342, in do_handshake
    self._sslobj.do_handshake()
urllib3.exceptions.ProtocolError: ('Connection aborted.', ConnectionResetError(10054, '远程主机强迫关闭了一个现有的连接。', None, 10054, None))

During handling of the above exception, another exception occurred:

Traceback (most recent call last):
  File "E:\WorkSpace\PythonWorkSpace\shopping_platform\venv\lib\site-packages\django\core\handlers\exception.py", line 55, in inner
    response = get_response(request)
  File "E:\WorkSpace\PythonWorkSpace\shopping_platform\venv\lib\site-packages\django\core\handlers\base.py", line 197, in _get_response
    response = wrapped_callback(request, *callback_args, **callback_kwargs)
  File "E:\WorkSpace\PythonWorkSpace\shopping_platform\venv\lib\site-packages\django\views\decorators\csrf.py", line 56, in wrapper_view
    return view_func(*args, **kwargs)
  File "E:\WorkSpace\PythonWorkSpace\shopping_platform\venv\lib\site-packages\django\views\generic\base.py", line 104, in view
    return self.dispatch(request, *args, **kwargs)
  File "E:\WorkSpace\PythonWorkSpace\shopping_platform\venv\lib\site-packages\rest_framework\views.py", line 509, in dispatch
    response = self.handle_exception(exc)
  File "E:\WorkSpace\PythonWorkSpace\shopping_platform\venv\lib\site-packages\rest_framework\views.py", line 469, in handle_exception
    self.raise_uncaught_exception(exc)
  File "E:\WorkSpace\PythonWorkSpace\shopping_platform\venv\lib\site-packages\rest_framework\views.py", line 480, in raise_uncaught_exception
    raise exc
  File "E:\WorkSpace\PythonWorkSpace\shopping_platform\venv\lib\site-packages\rest_framework\views.py", line 506, in dispatch
    response = handler(request, *args, **kwargs)
  File "E:\WorkSpace\PythonWorkSpace\shopping_platform\products\views.py", line 119, in delete
    result = requests.delete(url=url, headers=headers)
  File "E:\WorkSpace\PythonWorkSpace\shopping_platform\venv\lib\site-packages\requests\api.py", line 157, in delete
    return request("delete", url, **kwargs)
  File "E:\WorkSpace\PythonWorkSpace\shopping_platform\venv\lib\site-packages\requests\api.py", line 59, in request
    return session.request(method=method, url=url, **kwargs)
  File "E:\WorkSpace\PythonWorkSpace\shopping_platform\venv\lib\site-packages\requests\sessions.py", line 589, in request
    resp = self.send(prep, **send_kwargs)
  File "E:\WorkSpace\PythonWorkSpace\shopping_platform\venv\lib\site-packages\requests\sessions.py", line 703, in send
    r = adapter.send(request, **kwargs)
  File "E:\WorkSpace\PythonWorkSpace\shopping_platform\venv\lib\site-packages\requests\adapters.py", line 501, in send
    raise ConnectionError(err, request=request)
requests.exceptions.ConnectionError: ('Connection aborted.', ConnectionResetError(10054, '远程主机强迫关闭了一个现有的连接。', None, 10054, None))
31/May/2023 17:21:31 [Thread-1 (process_request_thread):17140] [django.request:241] [ERROR]- Internal Server Error: /shop/api/v1/categories/
Traceback (most recent call last):
  File "E:\WorkSpace\PythonWorkSpace\shopping_platform\venv\lib\site-packages\requests\models.py", line 971, in json
    return complexjson.loads(self.text, **kwargs)
  File "E:\software\Python\lib\json\__init__.py", line 346, in loads
    return _default_decoder.decode(s)
  File "E:\software\Python\lib\json\decoder.py", line 337, in decode
    obj, end = self.raw_decode(s, idx=_w(s, 0).end())
  File "E:\software\Python\lib\json\decoder.py", line 355, in raw_decode
    raise JSONDecodeError("Expecting value", s, err.value) from None
json.decoder.JSONDecodeError: Expecting value: line 1 column 1 (char 0)

During handling of the above exception, another exception occurred:

Traceback (most recent call last):
  File "E:\WorkSpace\PythonWorkSpace\shopping_platform\venv\lib\site-packages\django\core\handlers\exception.py", line 55, in inner
    response = get_response(request)
  File "E:\WorkSpace\PythonWorkSpace\shopping_platform\venv\lib\site-packages\django\core\handlers\base.py", line 197, in _get_response
    response = wrapped_callback(request, *callback_args, **callback_kwargs)
  File "E:\WorkSpace\PythonWorkSpace\shopping_platform\venv\lib\site-packages\django\views\decorators\csrf.py", line 56, in wrapper_view
    return view_func(*args, **kwargs)
  File "E:\WorkSpace\PythonWorkSpace\shopping_platform\venv\lib\site-packages\django\views\generic\base.py", line 104, in view
    return self.dispatch(request, *args, **kwargs)
  File "E:\WorkSpace\PythonWorkSpace\shopping_platform\venv\lib\site-packages\rest_framework\views.py", line 509, in dispatch
    response = self.handle_exception(exc)
  File "E:\WorkSpace\PythonWorkSpace\shopping_platform\venv\lib\site-packages\rest_framework\views.py", line 469, in handle_exception
    self.raise_uncaught_exception(exc)
  File "E:\WorkSpace\PythonWorkSpace\shopping_platform\venv\lib\site-packages\rest_framework\views.py", line 480, in raise_uncaught_exception
    raise exc
  File "E:\WorkSpace\PythonWorkSpace\shopping_platform\venv\lib\site-packages\rest_framework\views.py", line 506, in dispatch
    response = handler(request, *args, **kwargs)
  File "E:\WorkSpace\PythonWorkSpace\shopping_platform\products\views.py", line 129, in delete
    return Response(result.json(), status=result.status_code)
  File "E:\WorkSpace\PythonWorkSpace\shopping_platform\venv\lib\site-packages\requests\models.py", line 975, in json
    raise RequestsJSONDecodeError(e.msg, e.doc, e.pos)
requests.exceptions.JSONDecodeError: Expecting value: line 1 column 1 (char 0)
31/May/2023 17:28:15 [Thread-1 (process_request_thread):19372] [django.request:241] [ERROR]- Internal Server Error: /shop/api/v1/categories/
urllib3.exceptions.SSLError: EOF occurred in violation of protocol (_ssl.c:997)

The above exception was the direct cause of the following exception:

Traceback (most recent call last):
  File "E:\WorkSpace\PythonWorkSpace\shopping_platform\venv\lib\site-packages\requests\adapters.py", line 486, in send
    resp = conn.urlopen(
  File "E:\WorkSpace\PythonWorkSpace\shopping_platform\venv\lib\site-packages\urllib3\connectionpool.py", line 844, in urlopen
    retries = retries.increment(
  File "E:\WorkSpace\PythonWorkSpace\shopping_platform\venv\lib\site-packages\urllib3\util\retry.py", line 515, in increment
    raise MaxRetryError(_pool, url, reason) from reason  # type: ignore[arg-type]
urllib3.exceptions.MaxRetryError: HTTPSConnectionPool(host='api.bigcommerce.com', port=443): Max retries exceeded with url: /stores/rmz2xgu42d/v3/catalog/categories (Caused by SSLError(SSLEOFError(8, 'EOF occurred in violation of protocol (_ssl.c:997)')))

During handling of the above exception, another exception occurred:

Traceback (most recent call last):
  File "E:\WorkSpace\PythonWorkSpace\shopping_platform\venv\lib\site-packages\django\core\handlers\exception.py", line 55, in inner
    response = get_response(request)
  File "E:\WorkSpace\PythonWorkSpace\shopping_platform\venv\lib\site-packages\django\core\handlers\base.py", line 197, in _get_response
    response = wrapped_callback(request, *callback_args, **callback_kwargs)
  File "E:\WorkSpace\PythonWorkSpace\shopping_platform\venv\lib\site-packages\django\views\decorators\csrf.py", line 56, in wrapper_view
    return view_func(*args, **kwargs)
  File "E:\WorkSpace\PythonWorkSpace\shopping_platform\venv\lib\site-packages\django\views\generic\base.py", line 104, in view
    return self.dispatch(request, *args, **kwargs)
  File "E:\WorkSpace\PythonWorkSpace\shopping_platform\venv\lib\site-packages\rest_framework\views.py", line 509, in dispatch
    response = self.handle_exception(exc)
  File "E:\WorkSpace\PythonWorkSpace\shopping_platform\venv\lib\site-packages\rest_framework\views.py", line 469, in handle_exception
    self.raise_uncaught_exception(exc)
  File "E:\WorkSpace\PythonWorkSpace\shopping_platform\venv\lib\site-packages\rest_framework\views.py", line 480, in raise_uncaught_exception
    raise exc
  File "E:\WorkSpace\PythonWorkSpace\shopping_platform\venv\lib\site-packages\rest_framework\views.py", line 506, in dispatch
    response = handler(request, *args, **kwargs)
  File "E:\WorkSpace\PythonWorkSpace\shopping_platform\products\views.py", line 44, in post
    result = requests.post(url=cate_url, headers=headers, data=json.dumps(cate_data))
  File "E:\WorkSpace\PythonWorkSpace\shopping_platform\venv\lib\site-packages\requests\api.py", line 115, in post
    return request("post", url, data=data, json=json, **kwargs)
  File "E:\WorkSpace\PythonWorkSpace\shopping_platform\venv\lib\site-packages\requests\api.py", line 59, in request
    return session.request(method=method, url=url, **kwargs)
  File "E:\WorkSpace\PythonWorkSpace\shopping_platform\venv\lib\site-packages\requests\sessions.py", line 589, in request
    resp = self.send(prep, **send_kwargs)
  File "E:\WorkSpace\PythonWorkSpace\shopping_platform\venv\lib\site-packages\requests\sessions.py", line 703, in send
    r = adapter.send(request, **kwargs)
  File "E:\WorkSpace\PythonWorkSpace\shopping_platform\venv\lib\site-packages\requests\adapters.py", line 517, in send
    raise SSLError(e, request=request)
requests.exceptions.SSLError: HTTPSConnectionPool(host='api.bigcommerce.com', port=443): Max retries exceeded with url: /stores/rmz2xgu42d/v3/catalog/categories (Caused by SSLError(SSLEOFError(8, 'EOF occurred in violation of protocol (_ssl.c:997)')))
31/May/2023 17:31:14 [Thread-1 (process_request_thread):19372] [django.request:241] [ERROR]- Internal Server Error: /shop/api/v1/categories/
urllib3.exceptions.SSLError: EOF occurred in violation of protocol (_ssl.c:997)

The above exception was the direct cause of the following exception:

Traceback (most recent call last):
  File "E:\WorkSpace\PythonWorkSpace\shopping_platform\venv\lib\site-packages\requests\adapters.py", line 486, in send
    resp = conn.urlopen(
  File "E:\WorkSpace\PythonWorkSpace\shopping_platform\venv\lib\site-packages\urllib3\connectionpool.py", line 844, in urlopen
    retries = retries.increment(
  File "E:\WorkSpace\PythonWorkSpace\shopping_platform\venv\lib\site-packages\urllib3\util\retry.py", line 515, in increment
    raise MaxRetryError(_pool, url, reason) from reason  # type: ignore[arg-type]
urllib3.exceptions.MaxRetryError: HTTPSConnectionPool(host='api.bigcommerce.com', port=443): Max retries exceeded with url: /stores/rmz2xgu42d/v3/catalog/categories/32 (Caused by SSLError(SSLEOFError(8, 'EOF occurred in violation of protocol (_ssl.c:997)')))

During handling of the above exception, another exception occurred:

Traceback (most recent call last):
  File "E:\WorkSpace\PythonWorkSpace\shopping_platform\venv\lib\site-packages\django\core\handlers\exception.py", line 55, in inner
    response = get_response(request)
  File "E:\WorkSpace\PythonWorkSpace\shopping_platform\venv\lib\site-packages\django\core\handlers\base.py", line 197, in _get_response
    response = wrapped_callback(request, *callback_args, **callback_kwargs)
  File "E:\WorkSpace\PythonWorkSpace\shopping_platform\venv\lib\site-packages\django\views\decorators\csrf.py", line 56, in wrapper_view
    return view_func(*args, **kwargs)
  File "E:\WorkSpace\PythonWorkSpace\shopping_platform\venv\lib\site-packages\django\views\generic\base.py", line 104, in view
    return self.dispatch(request, *args, **kwargs)
  File "E:\WorkSpace\PythonWorkSpace\shopping_platform\venv\lib\site-packages\rest_framework\views.py", line 509, in dispatch
    response = self.handle_exception(exc)
  File "E:\WorkSpace\PythonWorkSpace\shopping_platform\venv\lib\site-packages\rest_framework\views.py", line 469, in handle_exception
    self.raise_uncaught_exception(exc)
  File "E:\WorkSpace\PythonWorkSpace\shopping_platform\venv\lib\site-packages\rest_framework\views.py", line 480, in raise_uncaught_exception
    raise exc
  File "E:\WorkSpace\PythonWorkSpace\shopping_platform\venv\lib\site-packages\rest_framework\views.py", line 506, in dispatch
    response = handler(request, *args, **kwargs)
  File "E:\WorkSpace\PythonWorkSpace\shopping_platform\products\views.py", line 119, in delete
    result = requests.delete(url=url, headers=headers)
  File "E:\WorkSpace\PythonWorkSpace\shopping_platform\venv\lib\site-packages\requests\api.py", line 157, in delete
    return request("delete", url, **kwargs)
  File "E:\WorkSpace\PythonWorkSpace\shopping_platform\venv\lib\site-packages\requests\api.py", line 59, in request
    return session.request(method=method, url=url, **kwargs)
  File "E:\WorkSpace\PythonWorkSpace\shopping_platform\venv\lib\site-packages\requests\sessions.py", line 589, in request
    resp = self.send(prep, **send_kwargs)
  File "E:\WorkSpace\PythonWorkSpace\shopping_platform\venv\lib\site-packages\requests\sessions.py", line 703, in send
    r = adapter.send(request, **kwargs)
  File "E:\WorkSpace\PythonWorkSpace\shopping_platform\venv\lib\site-packages\requests\adapters.py", line 517, in send
    raise SSLError(e, request=request)
requests.exceptions.SSLError: HTTPSConnectionPool(host='api.bigcommerce.com', port=443): Max retries exceeded with url: /stores/rmz2xgu42d/v3/catalog/categories/32 (Caused by SSLError(SSLEOFError(8, 'EOF occurred in violation of protocol (_ssl.c:997)')))
