29/May/2023 17:04:52 [Thread-2 (process_request_thread):22996] [django.request:241] [ERROR]- Internal Server Error: /shop/api/v1/customers/
Traceback (most recent call last):
  File "E:\WorkSpace\PythonWorkSpace\shopping_platform\venv\lib\site-packages\django\db\backends\utils.py", line 89, in _execute
    return self.cursor.execute(sql, params)
psycopg2.errors.UndefinedTable: 错误:  关系 "customers" 不存在
LINE 1: ...stomers"."phone", "customers"."new_password" FROM "customers...
                                                             ^


The above exception was the direct cause of the following exception:

Traceback (most recent call last):
  File "E:\WorkSpace\PythonWorkSpace\shopping_platform\venv\lib\site-packages\django\core\handlers\exception.py", line 55, in inner
    response = get_response(request)
  File "E:\WorkSpace\PythonWorkSpace\shopping_platform\venv\lib\site-packages\django\core\handlers\base.py", line 220, in _get_response
    response = response.render()
  File "E:\WorkSpace\PythonWorkSpace\shopping_platform\venv\lib\site-packages\django\template\response.py", line 114, in render
    self.content = self.rendered_content
  File "E:\WorkSpace\PythonWorkSpace\shopping_platform\venv\lib\site-packages\rest_framework\response.py", line 70, in rendered_content
    ret = renderer.render(self.data, accepted_media_type, context)
  File "E:\WorkSpace\PythonWorkSpace\shopping_platform\venv\lib\site-packages\rest_framework\renderers.py", line 723, in render
    context = self.get_context(data, accepted_media_type, renderer_context)
  File "E:\WorkSpace\PythonWorkSpace\shopping_platform\venv\lib\site-packages\rest_framework\renderers.py", line 679, in get_context
    'content': self.get_content(renderer, data, accepted_media_type, renderer_context),
  File "E:\WorkSpace\PythonWorkSpace\shopping_platform\venv\lib\site-packages\rest_framework\renderers.py", line 412, in get_content
    content = renderer.render(data, accepted_media_type, renderer_context)
  File "E:\WorkSpace\PythonWorkSpace\shopping_platform\venv\lib\site-packages\rest_framework\renderers.py", line 99, in render
    ret = json.dumps(
  File "E:\WorkSpace\PythonWorkSpace\shopping_platform\venv\lib\site-packages\rest_framework\utils\json.py", line 25, in dumps
    return json.dumps(*args, **kwargs)
  File "E:\software\Python\lib\json\__init__.py", line 238, in dumps
    **kw).encode(obj)
  File "E:\software\Python\lib\json\encoder.py", line 201, in encode
    chunks = list(chunks)
  File "E:\software\Python\lib\json\encoder.py", line 431, in _iterencode
    yield from _iterencode_dict(o, _current_indent_level)
  File "E:\software\Python\lib\json\encoder.py", line 405, in _iterencode_dict
    yield from chunks
  File "E:\software\Python\lib\json\encoder.py", line 405, in _iterencode_dict
    yield from chunks
  File "E:\software\Python\lib\json\encoder.py", line 438, in _iterencode
    o = _default(o)
  File "E:\WorkSpace\PythonWorkSpace\shopping_platform\venv\lib\site-packages\rest_framework\utils\encoders.py", line 47, in default
    return tuple(obj)
  File "E:\WorkSpace\PythonWorkSpace\shopping_platform\venv\lib\site-packages\django\db\models\query.py", line 398, in __iter__
    self._fetch_all()
  File "E:\WorkSpace\PythonWorkSpace\shopping_platform\venv\lib\site-packages\django\db\models\query.py", line 1881, in _fetch_all
    self._result_cache = list(self._iterable_class(self))
  File "E:\WorkSpace\PythonWorkSpace\shopping_platform\venv\lib\site-packages\django\db\models\query.py", line 91, in __iter__
    results = compiler.execute_sql(
  File "E:\WorkSpace\PythonWorkSpace\shopping_platform\venv\lib\site-packages\django\db\models\sql\compiler.py", line 1560, in execute_sql
    cursor.execute(sql, params)
  File "E:\WorkSpace\PythonWorkSpace\shopping_platform\venv\lib\site-packages\django\db\backends\utils.py", line 102, in execute
    return super().execute(sql, params)
  File "E:\WorkSpace\PythonWorkSpace\shopping_platform\venv\lib\site-packages\django\db\backends\utils.py", line 67, in execute
    return self._execute_with_wrappers(
  File "E:\WorkSpace\PythonWorkSpace\shopping_platform\venv\lib\site-packages\django\db\backends\utils.py", line 80, in _execute_with_wrappers
    return executor(sql, params, many, context)
  File "E:\WorkSpace\PythonWorkSpace\shopping_platform\venv\lib\site-packages\django\db\backends\utils.py", line 84, in _execute
    with self.db.wrap_database_errors:
  File "E:\WorkSpace\PythonWorkSpace\shopping_platform\venv\lib\site-packages\django\db\utils.py", line 91, in __exit__
    raise dj_exc_value.with_traceback(traceback) from exc_value
  File "E:\WorkSpace\PythonWorkSpace\shopping_platform\venv\lib\site-packages\django\db\backends\utils.py", line 89, in _execute
    return self.cursor.execute(sql, params)
django.db.utils.ProgrammingError: 错误:  关系 "customers" 不存在
LINE 1: ...stomers"."phone", "customers"."new_password" FROM "customers...
                                                             ^

29/May/2023 17:08:33 [Thread-6 (process_request_thread):24532] [django.request:241] [ERROR]- Internal Server Error: /shop/api/v1/customers/
Traceback (most recent call last):
  File "E:\WorkSpace\PythonWorkSpace\shopping_platform\venv\lib\site-packages\django\core\handlers\exception.py", line 55, in inner
    response = get_response(request)
  File "E:\WorkSpace\PythonWorkSpace\shopping_platform\venv\lib\site-packages\django\core\handlers\base.py", line 220, in _get_response
    response = response.render()
  File "E:\WorkSpace\PythonWorkSpace\shopping_platform\venv\lib\site-packages\django\template\response.py", line 114, in render
    self.content = self.rendered_content
  File "E:\WorkSpace\PythonWorkSpace\shopping_platform\venv\lib\site-packages\rest_framework\response.py", line 70, in rendered_content
    ret = renderer.render(self.data, accepted_media_type, context)
  File "E:\WorkSpace\PythonWorkSpace\shopping_platform\venv\lib\site-packages\rest_framework\renderers.py", line 723, in render
    context = self.get_context(data, accepted_media_type, renderer_context)
  File "E:\WorkSpace\PythonWorkSpace\shopping_platform\venv\lib\site-packages\rest_framework\renderers.py", line 679, in get_context
    'content': self.get_content(renderer, data, accepted_media_type, renderer_context),
  File "E:\WorkSpace\PythonWorkSpace\shopping_platform\venv\lib\site-packages\rest_framework\renderers.py", line 412, in get_content
    content = renderer.render(data, accepted_media_type, renderer_context)
  File "E:\WorkSpace\PythonWorkSpace\shopping_platform\venv\lib\site-packages\rest_framework\renderers.py", line 99, in render
    ret = json.dumps(
  File "E:\WorkSpace\PythonWorkSpace\shopping_platform\venv\lib\site-packages\rest_framework\utils\json.py", line 25, in dumps
    return json.dumps(*args, **kwargs)
  File "E:\software\Python\lib\json\__init__.py", line 238, in dumps
    **kw).encode(obj)
  File "E:\software\Python\lib\json\encoder.py", line 201, in encode
    chunks = list(chunks)
  File "E:\software\Python\lib\json\encoder.py", line 431, in _iterencode
    yield from _iterencode_dict(o, _current_indent_level)
  File "E:\software\Python\lib\json\encoder.py", line 405, in _iterencode_dict
    yield from chunks
  File "E:\software\Python\lib\json\encoder.py", line 405, in _iterencode_dict
    yield from chunks
  File "E:\software\Python\lib\json\encoder.py", line 439, in _iterencode
    yield from _iterencode(o, _current_indent_level)
  File "E:\software\Python\lib\json\encoder.py", line 429, in _iterencode
    yield from _iterencode_list(o, _current_indent_level)
  File "E:\software\Python\lib\json\encoder.py", line 325, in _iterencode_list
    yield from chunks
  File "E:\software\Python\lib\json\encoder.py", line 438, in _iterencode
    o = _default(o)
  File "E:\WorkSpace\PythonWorkSpace\shopping_platform\venv\lib\site-packages\rest_framework\utils\encoders.py", line 67, in default
    return super().default(obj)
  File "E:\software\Python\lib\json\encoder.py", line 179, in default
    raise TypeError(f'Object of type {o.__class__.__name__} '
TypeError: Object of type Customers is not JSON serializable
29/May/2023 17:53:46 [Thread-7 (process_request_thread):19116] [django.request:241] [ERROR]- Internal Server Error: /shop/api/v1/login/
Traceback (most recent call last):
  File "E:\WorkSpace\PythonWorkSpace\shopping_platform\venv\lib\site-packages\django\core\handlers\exception.py", line 55, in inner
    response = get_response(request)
  File "E:\WorkSpace\PythonWorkSpace\shopping_platform\venv\lib\site-packages\django\core\handlers\base.py", line 197, in _get_response
    response = wrapped_callback(request, *callback_args, **callback_kwargs)
  File "E:\WorkSpace\PythonWorkSpace\shopping_platform\venv\lib\site-packages\django\views\decorators\csrf.py", line 56, in wrapper_view
    return view_func(*args, **kwargs)
  File "E:\WorkSpace\PythonWorkSpace\shopping_platform\venv\lib\site-packages\django\views\generic\base.py", line 104, in view
    return self.dispatch(request, *args, **kwargs)
  File "E:\WorkSpace\PythonWorkSpace\shopping_platform\venv\lib\site-packages\rest_framework\views.py", line 509, in dispatch
    response = self.handle_exception(exc)
  File "E:\WorkSpace\PythonWorkSpace\shopping_platform\venv\lib\site-packages\rest_framework\views.py", line 469, in handle_exception
    self.raise_uncaught_exception(exc)
  File "E:\WorkSpace\PythonWorkSpace\shopping_platform\venv\lib\site-packages\rest_framework\views.py", line 480, in raise_uncaught_exception
    raise exc
  File "E:\WorkSpace\PythonWorkSpace\shopping_platform\venv\lib\site-packages\rest_framework\views.py", line 506, in dispatch
    response = handler(request, *args, **kwargs)
  File "E:\WorkSpace\PythonWorkSpace\shopping_platform\customers\views.py", line 40, in post
    email=login_data['email'],
KeyError: 'email'
29/May/2023 17:55:04 [Thread-7 (process_request_thread):19116] [django.request:241] [ERROR]- Internal Server Error: /shop/api/v1/login/
Traceback (most recent call last):
  File "E:\WorkSpace\PythonWorkSpace\shopping_platform\venv\lib\site-packages\django\core\handlers\exception.py", line 55, in inner
    response = get_response(request)
  File "E:\WorkSpace\PythonWorkSpace\shopping_platform\venv\lib\site-packages\django\core\handlers\base.py", line 197, in _get_response
    response = wrapped_callback(request, *callback_args, **callback_kwargs)
  File "E:\WorkSpace\PythonWorkSpace\shopping_platform\venv\lib\site-packages\django\views\decorators\csrf.py", line 56, in wrapper_view
    return view_func(*args, **kwargs)
  File "E:\WorkSpace\PythonWorkSpace\shopping_platform\venv\lib\site-packages\django\views\generic\base.py", line 104, in view
    return self.dispatch(request, *args, **kwargs)
  File "E:\WorkSpace\PythonWorkSpace\shopping_platform\venv\lib\site-packages\rest_framework\views.py", line 509, in dispatch
    response = self.handle_exception(exc)
  File "E:\WorkSpace\PythonWorkSpace\shopping_platform\venv\lib\site-packages\rest_framework\views.py", line 469, in handle_exception
    self.raise_uncaught_exception(exc)
  File "E:\WorkSpace\PythonWorkSpace\shopping_platform\venv\lib\site-packages\rest_framework\views.py", line 480, in raise_uncaught_exception
    raise exc
  File "E:\WorkSpace\PythonWorkSpace\shopping_platform\venv\lib\site-packages\rest_framework\views.py", line 506, in dispatch
    response = handler(request, *args, **kwargs)
  File "E:\WorkSpace\PythonWorkSpace\shopping_platform\customers\views.py", line 40, in post
    email=login_data['email'],
KeyError: 'email'
30/May/2023 09:33:33 [Thread-1 (process_request_thread):22280] [django.request:241] [ERROR]- Internal Server Error: /shop/api/v1/login/
Traceback (most recent call last):
  File "E:\WorkSpace\PythonWorkSpace\shopping_platform\venv\lib\site-packages\django\core\handlers\exception.py", line 55, in inner
    response = get_response(request)
  File "E:\WorkSpace\PythonWorkSpace\shopping_platform\venv\lib\site-packages\django\core\handlers\base.py", line 197, in _get_response
    response = wrapped_callback(request, *callback_args, **callback_kwargs)
  File "E:\WorkSpace\PythonWorkSpace\shopping_platform\venv\lib\site-packages\django\views\decorators\csrf.py", line 56, in wrapper_view
    return view_func(*args, **kwargs)
  File "E:\WorkSpace\PythonWorkSpace\shopping_platform\venv\lib\site-packages\django\views\generic\base.py", line 104, in view
    return self.dispatch(request, *args, **kwargs)
  File "E:\WorkSpace\PythonWorkSpace\shopping_platform\venv\lib\site-packages\rest_framework\views.py", line 509, in dispatch
    response = self.handle_exception(exc)
  File "E:\WorkSpace\PythonWorkSpace\shopping_platform\venv\lib\site-packages\rest_framework\views.py", line 469, in handle_exception
    self.raise_uncaught_exception(exc)
  File "E:\WorkSpace\PythonWorkSpace\shopping_platform\venv\lib\site-packages\rest_framework\views.py", line 480, in raise_uncaught_exception
    raise exc
  File "E:\WorkSpace\PythonWorkSpace\shopping_platform\venv\lib\site-packages\rest_framework\views.py", line 506, in dispatch
    response = handler(request, *args, **kwargs)
  File "E:\WorkSpace\PythonWorkSpace\shopping_platform\customers\views.py", line 40, in post
    email=login_data['email'],
KeyError: 'email'
30/May/2023 09:43:57 [Thread-1 (process_request_thread):22280] [django.request:241] [ERROR]- Internal Server Error: /shop/api/v1/login/
Traceback (most recent call last):
  File "E:\WorkSpace\PythonWorkSpace\shopping_platform\venv\lib\site-packages\django\core\handlers\exception.py", line 55, in inner
    response = get_response(request)
  File "E:\WorkSpace\PythonWorkSpace\shopping_platform\venv\lib\site-packages\django\core\handlers\base.py", line 197, in _get_response
    response = wrapped_callback(request, *callback_args, **callback_kwargs)
  File "E:\WorkSpace\PythonWorkSpace\shopping_platform\venv\lib\site-packages\django\views\decorators\csrf.py", line 56, in wrapper_view
    return view_func(*args, **kwargs)
  File "E:\WorkSpace\PythonWorkSpace\shopping_platform\venv\lib\site-packages\django\views\generic\base.py", line 104, in view
    return self.dispatch(request, *args, **kwargs)
  File "E:\WorkSpace\PythonWorkSpace\shopping_platform\venv\lib\site-packages\rest_framework\views.py", line 509, in dispatch
    response = self.handle_exception(exc)
  File "E:\WorkSpace\PythonWorkSpace\shopping_platform\venv\lib\site-packages\rest_framework\views.py", line 469, in handle_exception
    self.raise_uncaught_exception(exc)
  File "E:\WorkSpace\PythonWorkSpace\shopping_platform\venv\lib\site-packages\rest_framework\views.py", line 480, in raise_uncaught_exception
    raise exc
  File "E:\WorkSpace\PythonWorkSpace\shopping_platform\venv\lib\site-packages\rest_framework\views.py", line 506, in dispatch
    response = handler(request, *args, **kwargs)
  File "E:\WorkSpace\PythonWorkSpace\shopping_platform\customers\views.py", line 59, in post
    token = jwt.encode(payload, settings.SECRET_KEY)
AttributeError: module 'jwt' has no attribute 'encode'
30/May/2023 10:04:55 [Thread-1 (process_request_thread):16796] [django.request:241] [ERROR]- Internal Server Error: /shop/api/v1/login/
Traceback (most recent call last):
  File "E:\WorkSpace\PythonWorkSpace\shopping_platform\venv\lib\site-packages\django\core\handlers\exception.py", line 55, in inner
    response = get_response(request)
  File "E:\WorkSpace\PythonWorkSpace\shopping_platform\venv\lib\site-packages\django\core\handlers\base.py", line 197, in _get_response
    response = wrapped_callback(request, *callback_args, **callback_kwargs)
  File "E:\WorkSpace\PythonWorkSpace\shopping_platform\venv\lib\site-packages\django\views\decorators\csrf.py", line 56, in wrapper_view
    return view_func(*args, **kwargs)
  File "E:\WorkSpace\PythonWorkSpace\shopping_platform\venv\lib\site-packages\django\views\generic\base.py", line 104, in view
    return self.dispatch(request, *args, **kwargs)
  File "E:\WorkSpace\PythonWorkSpace\shopping_platform\venv\lib\site-packages\rest_framework\views.py", line 509, in dispatch
    response = self.handle_exception(exc)
  File "E:\WorkSpace\PythonWorkSpace\shopping_platform\venv\lib\site-packages\rest_framework\views.py", line 469, in handle_exception
    self.raise_uncaught_exception(exc)
  File "E:\WorkSpace\PythonWorkSpace\shopping_platform\venv\lib\site-packages\rest_framework\views.py", line 480, in raise_uncaught_exception
    raise exc
  File "E:\WorkSpace\PythonWorkSpace\shopping_platform\venv\lib\site-packages\rest_framework\views.py", line 506, in dispatch
    response = handler(request, *args, **kwargs)
  File "E:\WorkSpace\PythonWorkSpace\shopping_platform\customers\views.py", line 40, in post
    email=login_data['email'],
KeyError: 'email'
30/May/2023 10:32:06 [Thread-2 (process_request_thread):13300] [django.request:241] [ERROR]- Internal Server Error: /shop/api/v1/customers/
Traceback (most recent call last):
  File "E:\WorkSpace\PythonWorkSpace\shopping_platform\venv\lib\site-packages\django\core\handlers\exception.py", line 55, in inner
    response = get_response(request)
  File "E:\WorkSpace\PythonWorkSpace\shopping_platform\venv\lib\site-packages\django\core\handlers\base.py", line 197, in _get_response
    response = wrapped_callback(request, *callback_args, **callback_kwargs)
  File "E:\WorkSpace\PythonWorkSpace\shopping_platform\venv\lib\site-packages\django\views\decorators\csrf.py", line 56, in wrapper_view
    return view_func(*args, **kwargs)
  File "E:\WorkSpace\PythonWorkSpace\shopping_platform\venv\lib\site-packages\django\views\generic\base.py", line 104, in view
    return self.dispatch(request, *args, **kwargs)
  File "E:\WorkSpace\PythonWorkSpace\shopping_platform\venv\lib\site-packages\rest_framework\views.py", line 509, in dispatch
    response = self.handle_exception(exc)
  File "E:\WorkSpace\PythonWorkSpace\shopping_platform\venv\lib\site-packages\rest_framework\views.py", line 469, in handle_exception
    self.raise_uncaught_exception(exc)
  File "E:\WorkSpace\PythonWorkSpace\shopping_platform\venv\lib\site-packages\rest_framework\views.py", line 480, in raise_uncaught_exception
    raise exc
  File "E:\WorkSpace\PythonWorkSpace\shopping_platform\venv\lib\site-packages\rest_framework\views.py", line 506, in dispatch
    response = handler(request, *args, **kwargs)
  File "E:\WorkSpace\PythonWorkSpace\shopping_platform\customers\views.py", line 37, in get
    'data': {
TypeError: unhashable type: 'dict'
30/May/2023 10:33:58 [Thread-2 (process_request_thread):13180] [django.request:241] [ERROR]- Internal Server Error: /shop/api/v1/customers/
Traceback (most recent call last):
  File "E:\WorkSpace\PythonWorkSpace\shopping_platform\venv\lib\site-packages\django\core\handlers\exception.py", line 55, in inner
    response = get_response(request)
  File "E:\WorkSpace\PythonWorkSpace\shopping_platform\venv\lib\site-packages\django\core\handlers\base.py", line 197, in _get_response
    response = wrapped_callback(request, *callback_args, **callback_kwargs)
  File "E:\WorkSpace\PythonWorkSpace\shopping_platform\venv\lib\site-packages\django\views\decorators\csrf.py", line 56, in wrapper_view
    return view_func(*args, **kwargs)
  File "E:\WorkSpace\PythonWorkSpace\shopping_platform\venv\lib\site-packages\django\views\generic\base.py", line 104, in view
    return self.dispatch(request, *args, **kwargs)
  File "E:\WorkSpace\PythonWorkSpace\shopping_platform\venv\lib\site-packages\rest_framework\views.py", line 509, in dispatch
    response = self.handle_exception(exc)
  File "E:\WorkSpace\PythonWorkSpace\shopping_platform\venv\lib\site-packages\rest_framework\views.py", line 469, in handle_exception
    self.raise_uncaught_exception(exc)
  File "E:\WorkSpace\PythonWorkSpace\shopping_platform\venv\lib\site-packages\rest_framework\views.py", line 480, in raise_uncaught_exception
    raise exc
  File "E:\WorkSpace\PythonWorkSpace\shopping_platform\venv\lib\site-packages\rest_framework\views.py", line 506, in dispatch
    response = handler(request, *args, **kwargs)
  File "E:\WorkSpace\PythonWorkSpace\shopping_platform\customers\views.py", line 32, in get
    customers = result.json().data
AttributeError: 'dict' object has no attribute 'data'
30/May/2023 10:57:50 [Thread-1 (process_request_thread):9904] [django.request:241] [ERROR]- Internal Server Error: /shop/api/v1/login/
Traceback (most recent call last):
  File "E:\WorkSpace\PythonWorkSpace\shopping_platform\venv\lib\site-packages\django\core\handlers\exception.py", line 55, in inner
    response = get_response(request)
  File "E:\WorkSpace\PythonWorkSpace\shopping_platform\venv\lib\site-packages\django\core\handlers\base.py", line 197, in _get_response
    response = wrapped_callback(request, *callback_args, **callback_kwargs)
  File "E:\WorkSpace\PythonWorkSpace\shopping_platform\venv\lib\site-packages\django\views\decorators\csrf.py", line 56, in wrapper_view
    return view_func(*args, **kwargs)
  File "E:\WorkSpace\PythonWorkSpace\shopping_platform\venv\lib\site-packages\django\views\generic\base.py", line 104, in view
    return self.dispatch(request, *args, **kwargs)
  File "E:\WorkSpace\PythonWorkSpace\shopping_platform\venv\lib\site-packages\rest_framework\views.py", line 509, in dispatch
    response = self.handle_exception(exc)
  File "E:\WorkSpace\PythonWorkSpace\shopping_platform\venv\lib\site-packages\rest_framework\views.py", line 469, in handle_exception
    self.raise_uncaught_exception(exc)
  File "E:\WorkSpace\PythonWorkSpace\shopping_platform\venv\lib\site-packages\rest_framework\views.py", line 480, in raise_uncaught_exception
    raise exc
  File "E:\WorkSpace\PythonWorkSpace\shopping_platform\venv\lib\site-packages\rest_framework\views.py", line 506, in dispatch
    response = handler(request, *args, **kwargs)
  File "E:\WorkSpace\PythonWorkSpace\shopping_platform\customers\views.py", line 77, in post
    email=login_data['email'],
KeyError: 'email'
30/May/2023 10:58:25 [Thread-1 (process_request_thread):9904] [django.request:241] [ERROR]- Internal Server Error: /shop/api/v1/login/
Traceback (most recent call last):
  File "E:\WorkSpace\PythonWorkSpace\shopping_platform\venv\lib\site-packages\django\core\handlers\exception.py", line 55, in inner
    response = get_response(request)
  File "E:\WorkSpace\PythonWorkSpace\shopping_platform\venv\lib\site-packages\django\core\handlers\base.py", line 197, in _get_response
    response = wrapped_callback(request, *callback_args, **callback_kwargs)
  File "E:\WorkSpace\PythonWorkSpace\shopping_platform\venv\lib\site-packages\django\views\decorators\csrf.py", line 56, in wrapper_view
    return view_func(*args, **kwargs)
  File "E:\WorkSpace\PythonWorkSpace\shopping_platform\venv\lib\site-packages\django\views\generic\base.py", line 104, in view
    return self.dispatch(request, *args, **kwargs)
  File "E:\WorkSpace\PythonWorkSpace\shopping_platform\venv\lib\site-packages\rest_framework\views.py", line 509, in dispatch
    response = self.handle_exception(exc)
  File "E:\WorkSpace\PythonWorkSpace\shopping_platform\venv\lib\site-packages\rest_framework\views.py", line 469, in handle_exception
    self.raise_uncaught_exception(exc)
  File "E:\WorkSpace\PythonWorkSpace\shopping_platform\venv\lib\site-packages\rest_framework\views.py", line 480, in raise_uncaught_exception
    raise exc
  File "E:\WorkSpace\PythonWorkSpace\shopping_platform\venv\lib\site-packages\rest_framework\views.py", line 506, in dispatch
    response = handler(request, *args, **kwargs)
  File "E:\WorkSpace\PythonWorkSpace\shopping_platform\customers\views.py", line 78, in post
    new_password=login_data['new_password']
KeyError: 'new_password'
30/May/2023 11:01:37 [Thread-1 (process_request_thread):16604] [django.request:241] [ERROR]- Internal Server Error: /shop/api/v1/customers
Traceback (most recent call last):
  File "E:\WorkSpace\PythonWorkSpace\shopping_platform\venv\lib\site-packages\django\core\handlers\exception.py", line 55, in inner
    response = get_response(request)
  File "E:\WorkSpace\PythonWorkSpace\shopping_platform\venv\lib\site-packages\django\utils\deprecation.py", line 136, in __call__
    response = self.process_response(request, response)
  File "E:\WorkSpace\PythonWorkSpace\shopping_platform\venv\lib\site-packages\django\middleware\common.py", line 108, in process_response
    return self.response_redirect_class(self.get_full_path_with_slash(request))
  File "E:\WorkSpace\PythonWorkSpace\shopping_platform\venv\lib\site-packages\django\middleware\common.py", line 87, in get_full_path_with_slash
    raise RuntimeError(
RuntimeError: You called this URL via POST, but the URL doesn't end in a slash and you have APPEND_SLASH set. Django can't redirect to the slash URL while maintaining POST data. Change your form to point to 127.0.0.1:8000/shop/api/v1/customers/ (note the trailing slash), or set APPEND_SLASH=False in your Django settings.
30/May/2023 11:03:03 [Thread-2 (process_request_thread):21880] [django.request:241] [ERROR]- Internal Server Error: /shop/api/v1/customers/
Traceback (most recent call last):
  File "E:\WorkSpace\PythonWorkSpace\shopping_platform\venv\lib\site-packages\django\core\handlers\exception.py", line 55, in inner
    response = get_response(request)
  File "E:\WorkSpace\PythonWorkSpace\shopping_platform\venv\lib\site-packages\django\core\handlers\base.py", line 197, in _get_response
    response = wrapped_callback(request, *callback_args, **callback_kwargs)
  File "E:\WorkSpace\PythonWorkSpace\shopping_platform\venv\lib\site-packages\django\views\decorators\csrf.py", line 56, in wrapper_view
    return view_func(*args, **kwargs)
  File "E:\WorkSpace\PythonWorkSpace\shopping_platform\venv\lib\site-packages\django\views\generic\base.py", line 104, in view
    return self.dispatch(request, *args, **kwargs)
  File "E:\WorkSpace\PythonWorkSpace\shopping_platform\venv\lib\site-packages\rest_framework\views.py", line 509, in dispatch
    response = self.handle_exception(exc)
  File "E:\WorkSpace\PythonWorkSpace\shopping_platform\venv\lib\site-packages\rest_framework\views.py", line 469, in handle_exception
    self.raise_uncaught_exception(exc)
  File "E:\WorkSpace\PythonWorkSpace\shopping_platform\venv\lib\site-packages\rest_framework\views.py", line 480, in raise_uncaught_exception
    raise exc
  File "E:\WorkSpace\PythonWorkSpace\shopping_platform\venv\lib\site-packages\rest_framework\views.py", line 506, in dispatch
    response = handler(request, *args, **kwargs)
  File "E:\WorkSpace\PythonWorkSpace\shopping_platform\customers\views.py", line 50, in post
    first_name=customer_data['first_name'],
TypeError: list indices must be integers or slices, not str
30/May/2023 11:03:34 [Thread-2 (process_request_thread):21880] [django.request:241] [ERROR]- Internal Server Error: /shop/api/v1/customers/
Traceback (most recent call last):
  File "E:\WorkSpace\PythonWorkSpace\shopping_platform\venv\lib\site-packages\urllib3\connectionpool.py", line 776, in urlopen
    self._prepare_proxy(conn)
  File "E:\WorkSpace\PythonWorkSpace\shopping_platform\venv\lib\site-packages\urllib3\connectionpool.py", line 1041, in _prepare_proxy
    conn.connect()
  File "E:\WorkSpace\PythonWorkSpace\shopping_platform\venv\lib\site-packages\urllib3\connection.py", line 635, in connect
    sock_and_verified = _ssl_wrap_socket_and_match_hostname(
  File "E:\WorkSpace\PythonWorkSpace\shopping_platform\venv\lib\site-packages\urllib3\connection.py", line 774, in _ssl_wrap_socket_and_match_hostname
    ssl_sock = ssl_wrap_socket(
  File "E:\WorkSpace\PythonWorkSpace\shopping_platform\venv\lib\site-packages\urllib3\util\ssl_.py", line 459, in ssl_wrap_socket
    ssl_sock = _ssl_wrap_socket_impl(sock, context, tls_in_tls, server_hostname)
  File "E:\WorkSpace\PythonWorkSpace\shopping_platform\venv\lib\site-packages\urllib3\util\ssl_.py", line 503, in _ssl_wrap_socket_impl
    return ssl_context.wrap_socket(sock, server_hostname=server_hostname)
  File "E:\software\Python\lib\ssl.py", line 513, in wrap_socket
    return self.sslsocket_class._create(
  File "E:\software\Python\lib\ssl.py", line 1071, in _create
    self.do_handshake()
  File "E:\software\Python\lib\ssl.py", line 1342, in do_handshake
    self._sslobj.do_handshake()
ConnectionResetError: [WinError 10054] 远程主机强迫关闭了一个现有的连接。

During handling of the above exception, another exception occurred:

Traceback (most recent call last):
  File "E:\WorkSpace\PythonWorkSpace\shopping_platform\venv\lib\site-packages\requests\adapters.py", line 486, in send
    resp = conn.urlopen(
  File "E:\WorkSpace\PythonWorkSpace\shopping_platform\venv\lib\site-packages\urllib3\connectionpool.py", line 844, in urlopen
    retries = retries.increment(
  File "E:\WorkSpace\PythonWorkSpace\shopping_platform\venv\lib\site-packages\urllib3\util\retry.py", line 470, in increment
    raise reraise(type(error), error, _stacktrace)
  File "E:\WorkSpace\PythonWorkSpace\shopping_platform\venv\lib\site-packages\urllib3\util\util.py", line 38, in reraise
    raise value.with_traceback(tb)
  File "E:\WorkSpace\PythonWorkSpace\shopping_platform\venv\lib\site-packages\urllib3\connectionpool.py", line 776, in urlopen
    self._prepare_proxy(conn)
  File "E:\WorkSpace\PythonWorkSpace\shopping_platform\venv\lib\site-packages\urllib3\connectionpool.py", line 1041, in _prepare_proxy
    conn.connect()
  File "E:\WorkSpace\PythonWorkSpace\shopping_platform\venv\lib\site-packages\urllib3\connection.py", line 635, in connect
    sock_and_verified = _ssl_wrap_socket_and_match_hostname(
  File "E:\WorkSpace\PythonWorkSpace\shopping_platform\venv\lib\site-packages\urllib3\connection.py", line 774, in _ssl_wrap_socket_and_match_hostname
    ssl_sock = ssl_wrap_socket(
  File "E:\WorkSpace\PythonWorkSpace\shopping_platform\venv\lib\site-packages\urllib3\util\ssl_.py", line 459, in ssl_wrap_socket
    ssl_sock = _ssl_wrap_socket_impl(sock, context, tls_in_tls, server_hostname)
  File "E:\WorkSpace\PythonWorkSpace\shopping_platform\venv\lib\site-packages\urllib3\util\ssl_.py", line 503, in _ssl_wrap_socket_impl
    return ssl_context.wrap_socket(sock, server_hostname=server_hostname)
  File "E:\software\Python\lib\ssl.py", line 513, in wrap_socket
    return self.sslsocket_class._create(
  File "E:\software\Python\lib\ssl.py", line 1071, in _create
    self.do_handshake()
  File "E:\software\Python\lib\ssl.py", line 1342, in do_handshake
    self._sslobj.do_handshake()
urllib3.exceptions.ProtocolError: ('Connection aborted.', ConnectionResetError(10054, '远程主机强迫关闭了一个现有的连接。', None, 10054, None))

During handling of the above exception, another exception occurred:

Traceback (most recent call last):
  File "E:\WorkSpace\PythonWorkSpace\shopping_platform\venv\lib\site-packages\django\core\handlers\exception.py", line 55, in inner
    response = get_response(request)
  File "E:\WorkSpace\PythonWorkSpace\shopping_platform\venv\lib\site-packages\django\core\handlers\base.py", line 197, in _get_response
    response = wrapped_callback(request, *callback_args, **callback_kwargs)
  File "E:\WorkSpace\PythonWorkSpace\shopping_platform\venv\lib\site-packages\django\views\decorators\csrf.py", line 56, in wrapper_view
    return view_func(*args, **kwargs)
  File "E:\WorkSpace\PythonWorkSpace\shopping_platform\venv\lib\site-packages\django\views\generic\base.py", line 104, in view
    return self.dispatch(request, *args, **kwargs)
  File "E:\WorkSpace\PythonWorkSpace\shopping_platform\venv\lib\site-packages\rest_framework\views.py", line 509, in dispatch
    response = self.handle_exception(exc)
  File "E:\WorkSpace\PythonWorkSpace\shopping_platform\venv\lib\site-packages\rest_framework\views.py", line 469, in handle_exception
    self.raise_uncaught_exception(exc)
  File "E:\WorkSpace\PythonWorkSpace\shopping_platform\venv\lib\site-packages\rest_framework\views.py", line 480, in raise_uncaught_exception
    raise exc
  File "E:\WorkSpace\PythonWorkSpace\shopping_platform\venv\lib\site-packages\rest_framework\views.py", line 506, in dispatch
    response = handler(request, *args, **kwargs)
  File "E:\WorkSpace\PythonWorkSpace\shopping_platform\customers\views.py", line 62, in post
    result = requests.post(url, data=body, headers=headers)
  File "E:\WorkSpace\PythonWorkSpace\shopping_platform\venv\lib\site-packages\requests\api.py", line 115, in post
    return request("post", url, data=data, json=json, **kwargs)
  File "E:\WorkSpace\PythonWorkSpace\shopping_platform\venv\lib\site-packages\requests\api.py", line 59, in request
    return session.request(method=method, url=url, **kwargs)
  File "E:\WorkSpace\PythonWorkSpace\shopping_platform\venv\lib\site-packages\requests\sessions.py", line 589, in request
    resp = self.send(prep, **send_kwargs)
  File "E:\WorkSpace\PythonWorkSpace\shopping_platform\venv\lib\site-packages\requests\sessions.py", line 703, in send
    r = adapter.send(request, **kwargs)
  File "E:\WorkSpace\PythonWorkSpace\shopping_platform\venv\lib\site-packages\requests\adapters.py", line 501, in send
    raise ConnectionError(err, request=request)
requests.exceptions.ConnectionError: ('Connection aborted.', ConnectionResetError(10054, '远程主机强迫关闭了一个现有的连接。', None, 10054, None))
30/May/2023 11:11:02 [Thread-1 (process_request_thread):5704] [django.request:241] [ERROR]- Internal Server Error: /shop/api/v1/customers/
Traceback (most recent call last):
  File "E:\WorkSpace\PythonWorkSpace\shopping_platform\venv\lib\site-packages\django\core\handlers\exception.py", line 55, in inner
    response = get_response(request)
  File "E:\WorkSpace\PythonWorkSpace\shopping_platform\venv\lib\site-packages\django\core\handlers\base.py", line 197, in _get_response
    response = wrapped_callback(request, *callback_args, **callback_kwargs)
  File "E:\WorkSpace\PythonWorkSpace\shopping_platform\venv\lib\site-packages\django\views\decorators\csrf.py", line 56, in wrapper_view
    return view_func(*args, **kwargs)
  File "E:\WorkSpace\PythonWorkSpace\shopping_platform\venv\lib\site-packages\django\views\generic\base.py", line 104, in view
    return self.dispatch(request, *args, **kwargs)
  File "E:\WorkSpace\PythonWorkSpace\shopping_platform\venv\lib\site-packages\rest_framework\views.py", line 509, in dispatch
    response = self.handle_exception(exc)
  File "E:\WorkSpace\PythonWorkSpace\shopping_platform\venv\lib\site-packages\rest_framework\views.py", line 469, in handle_exception
    self.raise_uncaught_exception(exc)
  File "E:\WorkSpace\PythonWorkSpace\shopping_platform\venv\lib\site-packages\rest_framework\views.py", line 480, in raise_uncaught_exception
    raise exc
  File "E:\WorkSpace\PythonWorkSpace\shopping_platform\venv\lib\site-packages\rest_framework\views.py", line 506, in dispatch
    response = handler(request, *args, **kwargs)
  File "E:\WorkSpace\PythonWorkSpace\shopping_platform\customers\views.py", line 46, in post
    customer_data = requset.data[0]
KeyError: 0
30/May/2023 11:11:40 [Thread-1 (process_request_thread):5704] [django.request:241] [ERROR]- Internal Server Error: /shop/api/v1/customers/
Traceback (most recent call last):
  File "E:\WorkSpace\PythonWorkSpace\shopping_platform\venv\lib\site-packages\django\core\handlers\exception.py", line 55, in inner
    response = get_response(request)
  File "E:\WorkSpace\PythonWorkSpace\shopping_platform\venv\lib\site-packages\django\core\handlers\base.py", line 197, in _get_response
    response = wrapped_callback(request, *callback_args, **callback_kwargs)
  File "E:\WorkSpace\PythonWorkSpace\shopping_platform\venv\lib\site-packages\django\views\decorators\csrf.py", line 56, in wrapper_view
    return view_func(*args, **kwargs)
  File "E:\WorkSpace\PythonWorkSpace\shopping_platform\venv\lib\site-packages\django\views\generic\base.py", line 104, in view
    return self.dispatch(request, *args, **kwargs)
  File "E:\WorkSpace\PythonWorkSpace\shopping_platform\venv\lib\site-packages\rest_framework\views.py", line 509, in dispatch
    response = self.handle_exception(exc)
  File "E:\WorkSpace\PythonWorkSpace\shopping_platform\venv\lib\site-packages\rest_framework\views.py", line 469, in handle_exception
    self.raise_uncaught_exception(exc)
  File "E:\WorkSpace\PythonWorkSpace\shopping_platform\venv\lib\site-packages\rest_framework\views.py", line 480, in raise_uncaught_exception
    raise exc
  File "E:\WorkSpace\PythonWorkSpace\shopping_platform\venv\lib\site-packages\rest_framework\views.py", line 506, in dispatch
    response = handler(request, *args, **kwargs)
  File "E:\WorkSpace\PythonWorkSpace\shopping_platform\customers\views.py", line 51, in post
    result = requests.post(url, data=body, headers=headers)
  File "E:\WorkSpace\PythonWorkSpace\shopping_platform\venv\lib\site-packages\requests\api.py", line 115, in post
    return request("post", url, data=data, json=json, **kwargs)
  File "E:\WorkSpace\PythonWorkSpace\shopping_platform\venv\lib\site-packages\requests\api.py", line 59, in request
    return session.request(method=method, url=url, **kwargs)
  File "E:\WorkSpace\PythonWorkSpace\shopping_platform\venv\lib\site-packages\requests\sessions.py", line 575, in request
    prep = self.prepare_request(req)
  File "E:\WorkSpace\PythonWorkSpace\shopping_platform\venv\lib\site-packages\requests\sessions.py", line 486, in prepare_request
    p.prepare(
  File "E:\WorkSpace\PythonWorkSpace\shopping_platform\venv\lib\site-packages\requests\models.py", line 371, in prepare
    self.prepare_body(data, files, json)
  File "E:\WorkSpace\PythonWorkSpace\shopping_platform\venv\lib\site-packages\requests\models.py", line 559, in prepare_body
    body = self._encode_params(data)
  File "E:\WorkSpace\PythonWorkSpace\shopping_platform\venv\lib\site-packages\requests\models.py", line 121, in _encode_params
    for k, vs in to_key_val_list(data):
ValueError: too many values to unpack (expected 2)
30/May/2023 11:13:31 [Thread-1 (process_request_thread):21096] [django.request:241] [ERROR]- Internal Server Error: /shop/api/v1/customers/
Traceback (most recent call last):
  File "E:\WorkSpace\PythonWorkSpace\shopping_platform\venv\lib\site-packages\django\core\handlers\exception.py", line 55, in inner
    response = get_response(request)
  File "E:\WorkSpace\PythonWorkSpace\shopping_platform\venv\lib\site-packages\django\core\handlers\base.py", line 197, in _get_response
    response = wrapped_callback(request, *callback_args, **callback_kwargs)
  File "E:\WorkSpace\PythonWorkSpace\shopping_platform\venv\lib\site-packages\django\views\decorators\csrf.py", line 56, in wrapper_view
    return view_func(*args, **kwargs)
  File "E:\WorkSpace\PythonWorkSpace\shopping_platform\venv\lib\site-packages\django\views\generic\base.py", line 104, in view
    return self.dispatch(request, *args, **kwargs)
  File "E:\WorkSpace\PythonWorkSpace\shopping_platform\venv\lib\site-packages\rest_framework\views.py", line 509, in dispatch
    response = self.handle_exception(exc)
  File "E:\WorkSpace\PythonWorkSpace\shopping_platform\venv\lib\site-packages\rest_framework\views.py", line 469, in handle_exception
    self.raise_uncaught_exception(exc)
  File "E:\WorkSpace\PythonWorkSpace\shopping_platform\venv\lib\site-packages\rest_framework\views.py", line 480, in raise_uncaught_exception
    raise exc
  File "E:\WorkSpace\PythonWorkSpace\shopping_platform\venv\lib\site-packages\rest_framework\views.py", line 506, in dispatch
    response = handler(request, *args, **kwargs)
  File "E:\WorkSpace\PythonWorkSpace\shopping_platform\customers\views.py", line 51, in post
    result = requests.post(url, data=body, headers=headers)
  File "E:\WorkSpace\PythonWorkSpace\shopping_platform\venv\lib\site-packages\requests\api.py", line 115, in post
    return request("post", url, data=data, json=json, **kwargs)
  File "E:\WorkSpace\PythonWorkSpace\shopping_platform\venv\lib\site-packages\requests\api.py", line 59, in request
    return session.request(method=method, url=url, **kwargs)
  File "E:\WorkSpace\PythonWorkSpace\shopping_platform\venv\lib\site-packages\requests\sessions.py", line 575, in request
    prep = self.prepare_request(req)
  File "E:\WorkSpace\PythonWorkSpace\shopping_platform\venv\lib\site-packages\requests\sessions.py", line 486, in prepare_request
    p.prepare(
  File "E:\WorkSpace\PythonWorkSpace\shopping_platform\venv\lib\site-packages\requests\models.py", line 371, in prepare
    self.prepare_body(data, files, json)
  File "E:\WorkSpace\PythonWorkSpace\shopping_platform\venv\lib\site-packages\requests\models.py", line 559, in prepare_body
    body = self._encode_params(data)
  File "E:\WorkSpace\PythonWorkSpace\shopping_platform\venv\lib\site-packages\requests\models.py", line 121, in _encode_params
    for k, vs in to_key_val_list(data):
ValueError: too many values to unpack (expected 2)
30/May/2023 11:17:32 [Thread-1 (process_request_thread):22164] [django.request:241] [ERROR]- Internal Server Error: /shop/api/v1/customers/
Traceback (most recent call last):
  File "E:\WorkSpace\PythonWorkSpace\shopping_platform\venv\lib\site-packages\django\core\handlers\exception.py", line 55, in inner
    response = get_response(request)
  File "E:\WorkSpace\PythonWorkSpace\shopping_platform\venv\lib\site-packages\django\core\handlers\base.py", line 197, in _get_response
    response = wrapped_callback(request, *callback_args, **callback_kwargs)
  File "E:\WorkSpace\PythonWorkSpace\shopping_platform\venv\lib\site-packages\django\views\decorators\csrf.py", line 56, in wrapper_view
    return view_func(*args, **kwargs)
  File "E:\WorkSpace\PythonWorkSpace\shopping_platform\venv\lib\site-packages\django\views\generic\base.py", line 104, in view
    return self.dispatch(request, *args, **kwargs)
  File "E:\WorkSpace\PythonWorkSpace\shopping_platform\venv\lib\site-packages\rest_framework\views.py", line 509, in dispatch
    response = self.handle_exception(exc)
  File "E:\WorkSpace\PythonWorkSpace\shopping_platform\venv\lib\site-packages\rest_framework\views.py", line 469, in handle_exception
    self.raise_uncaught_exception(exc)
  File "E:\WorkSpace\PythonWorkSpace\shopping_platform\venv\lib\site-packages\rest_framework\views.py", line 480, in raise_uncaught_exception
    raise exc
  File "E:\WorkSpace\PythonWorkSpace\shopping_platform\venv\lib\site-packages\rest_framework\views.py", line 506, in dispatch
    response = handler(request, *args, **kwargs)
  File "E:\WorkSpace\PythonWorkSpace\shopping_platform\customers\views.py", line 51, in post
    result = requests.post(url, data=body, headers=headers)
  File "E:\WorkSpace\PythonWorkSpace\shopping_platform\venv\lib\site-packages\requests\api.py", line 115, in post
    return request("post", url, data=data, json=json, **kwargs)
  File "E:\WorkSpace\PythonWorkSpace\shopping_platform\venv\lib\site-packages\requests\api.py", line 59, in request
    return session.request(method=method, url=url, **kwargs)
  File "E:\WorkSpace\PythonWorkSpace\shopping_platform\venv\lib\site-packages\requests\sessions.py", line 575, in request
    prep = self.prepare_request(req)
  File "E:\WorkSpace\PythonWorkSpace\shopping_platform\venv\lib\site-packages\requests\sessions.py", line 486, in prepare_request
    p.prepare(
  File "E:\WorkSpace\PythonWorkSpace\shopping_platform\venv\lib\site-packages\requests\models.py", line 371, in prepare
    self.prepare_body(data, files, json)
  File "E:\WorkSpace\PythonWorkSpace\shopping_platform\venv\lib\site-packages\requests\models.py", line 559, in prepare_body
    body = self._encode_params(data)
  File "E:\WorkSpace\PythonWorkSpace\shopping_platform\venv\lib\site-packages\requests\models.py", line 121, in _encode_params
    for k, vs in to_key_val_list(data):
ValueError: too many values to unpack (expected 2)
30/May/2023 11:20:31 [Thread-1 (process_request_thread):21888] [django.request:241] [ERROR]- Internal Server Error: /shop/api/v1/customers/
Traceback (most recent call last):
  File "E:\WorkSpace\PythonWorkSpace\shopping_platform\venv\lib\site-packages\django\core\handlers\exception.py", line 55, in inner
    response = get_response(request)
  File "E:\WorkSpace\PythonWorkSpace\shopping_platform\venv\lib\site-packages\django\core\handlers\base.py", line 197, in _get_response
    response = wrapped_callback(request, *callback_args, **callback_kwargs)
  File "E:\WorkSpace\PythonWorkSpace\shopping_platform\venv\lib\site-packages\django\views\decorators\csrf.py", line 56, in wrapper_view
    return view_func(*args, **kwargs)
  File "E:\WorkSpace\PythonWorkSpace\shopping_platform\venv\lib\site-packages\django\views\generic\base.py", line 104, in view
    return self.dispatch(request, *args, **kwargs)
  File "E:\WorkSpace\PythonWorkSpace\shopping_platform\venv\lib\site-packages\rest_framework\views.py", line 509, in dispatch
    response = self.handle_exception(exc)
  File "E:\WorkSpace\PythonWorkSpace\shopping_platform\venv\lib\site-packages\rest_framework\views.py", line 469, in handle_exception
    self.raise_uncaught_exception(exc)
  File "E:\WorkSpace\PythonWorkSpace\shopping_platform\venv\lib\site-packages\rest_framework\views.py", line 480, in raise_uncaught_exception
    raise exc
  File "E:\WorkSpace\PythonWorkSpace\shopping_platform\venv\lib\site-packages\rest_framework\views.py", line 506, in dispatch
    response = handler(request, *args, **kwargs)
  File "E:\WorkSpace\PythonWorkSpace\shopping_platform\customers\views.py", line 51, in post
    result = requests.post(url, data=body, headers=headers)
  File "E:\WorkSpace\PythonWorkSpace\shopping_platform\venv\lib\site-packages\requests\api.py", line 115, in post
    return request("post", url, data=data, json=json, **kwargs)
  File "E:\WorkSpace\PythonWorkSpace\shopping_platform\venv\lib\site-packages\requests\api.py", line 59, in request
    return session.request(method=method, url=url, **kwargs)
  File "E:\WorkSpace\PythonWorkSpace\shopping_platform\venv\lib\site-packages\requests\sessions.py", line 575, in request
    prep = self.prepare_request(req)
  File "E:\WorkSpace\PythonWorkSpace\shopping_platform\venv\lib\site-packages\requests\sessions.py", line 486, in prepare_request
    p.prepare(
  File "E:\WorkSpace\PythonWorkSpace\shopping_platform\venv\lib\site-packages\requests\models.py", line 371, in prepare
    self.prepare_body(data, files, json)
  File "E:\WorkSpace\PythonWorkSpace\shopping_platform\venv\lib\site-packages\requests\models.py", line 559, in prepare_body
    body = self._encode_params(data)
  File "E:\WorkSpace\PythonWorkSpace\shopping_platform\venv\lib\site-packages\requests\models.py", line 121, in _encode_params
    for k, vs in to_key_val_list(data):
ValueError: too many values to unpack (expected 2)
30/May/2023 11:21:24 [Thread-5 (process_request_thread):7704] [django.request:241] [ERROR]- Internal Server Error: /shop/api/v1/customers/
Traceback (most recent call last):
  File "E:\WorkSpace\PythonWorkSpace\shopping_platform\venv\lib\site-packages\django\core\handlers\exception.py", line 55, in inner
    response = get_response(request)
  File "E:\WorkSpace\PythonWorkSpace\shopping_platform\venv\lib\site-packages\django\core\handlers\base.py", line 197, in _get_response
    response = wrapped_callback(request, *callback_args, **callback_kwargs)
  File "E:\WorkSpace\PythonWorkSpace\shopping_platform\venv\lib\site-packages\django\views\decorators\csrf.py", line 56, in wrapper_view
    return view_func(*args, **kwargs)
  File "E:\WorkSpace\PythonWorkSpace\shopping_platform\venv\lib\site-packages\django\views\generic\base.py", line 104, in view
    return self.dispatch(request, *args, **kwargs)
  File "E:\WorkSpace\PythonWorkSpace\shopping_platform\venv\lib\site-packages\rest_framework\views.py", line 509, in dispatch
    response = self.handle_exception(exc)
  File "E:\WorkSpace\PythonWorkSpace\shopping_platform\venv\lib\site-packages\rest_framework\views.py", line 469, in handle_exception
    self.raise_uncaught_exception(exc)
  File "E:\WorkSpace\PythonWorkSpace\shopping_platform\venv\lib\site-packages\rest_framework\views.py", line 480, in raise_uncaught_exception
    raise exc
  File "E:\WorkSpace\PythonWorkSpace\shopping_platform\venv\lib\site-packages\rest_framework\views.py", line 506, in dispatch
    response = handler(request, *args, **kwargs)
  File "E:\WorkSpace\PythonWorkSpace\shopping_platform\customers\views.py", line 51, in post
    result = requests.post(url, data=body, headers=headers)
  File "E:\WorkSpace\PythonWorkSpace\shopping_platform\venv\lib\site-packages\requests\api.py", line 115, in post
    return request("post", url, data=data, json=json, **kwargs)
  File "E:\WorkSpace\PythonWorkSpace\shopping_platform\venv\lib\site-packages\requests\api.py", line 59, in request
    return session.request(method=method, url=url, **kwargs)
  File "E:\WorkSpace\PythonWorkSpace\shopping_platform\venv\lib\site-packages\requests\sessions.py", line 575, in request
    prep = self.prepare_request(req)
  File "E:\WorkSpace\PythonWorkSpace\shopping_platform\venv\lib\site-packages\requests\sessions.py", line 486, in prepare_request
    p.prepare(
  File "E:\WorkSpace\PythonWorkSpace\shopping_platform\venv\lib\site-packages\requests\models.py", line 371, in prepare
    self.prepare_body(data, files, json)
  File "E:\WorkSpace\PythonWorkSpace\shopping_platform\venv\lib\site-packages\requests\models.py", line 559, in prepare_body
    body = self._encode_params(data)
  File "E:\WorkSpace\PythonWorkSpace\shopping_platform\venv\lib\site-packages\requests\models.py", line 121, in _encode_params
    for k, vs in to_key_val_list(data):
ValueError: too many values to unpack (expected 2)
30/May/2023 11:23:54 [Thread-1 (process_request_thread):8580] [django.request:241] [ERROR]- Internal Server Error: /shop/api/v1/customers/
Traceback (most recent call last):
  File "E:\WorkSpace\PythonWorkSpace\shopping_platform\venv\lib\site-packages\urllib3\connectionpool.py", line 776, in urlopen
    self._prepare_proxy(conn)
  File "E:\WorkSpace\PythonWorkSpace\shopping_platform\venv\lib\site-packages\urllib3\connectionpool.py", line 1041, in _prepare_proxy
    conn.connect()
  File "E:\WorkSpace\PythonWorkSpace\shopping_platform\venv\lib\site-packages\urllib3\connection.py", line 635, in connect
    sock_and_verified = _ssl_wrap_socket_and_match_hostname(
  File "E:\WorkSpace\PythonWorkSpace\shopping_platform\venv\lib\site-packages\urllib3\connection.py", line 774, in _ssl_wrap_socket_and_match_hostname
    ssl_sock = ssl_wrap_socket(
  File "E:\WorkSpace\PythonWorkSpace\shopping_platform\venv\lib\site-packages\urllib3\util\ssl_.py", line 459, in ssl_wrap_socket
    ssl_sock = _ssl_wrap_socket_impl(sock, context, tls_in_tls, server_hostname)
  File "E:\WorkSpace\PythonWorkSpace\shopping_platform\venv\lib\site-packages\urllib3\util\ssl_.py", line 503, in _ssl_wrap_socket_impl
    return ssl_context.wrap_socket(sock, server_hostname=server_hostname)
  File "E:\software\Python\lib\ssl.py", line 513, in wrap_socket
    return self.sslsocket_class._create(
  File "E:\software\Python\lib\ssl.py", line 1071, in _create
    self.do_handshake()
  File "E:\software\Python\lib\ssl.py", line 1342, in do_handshake
    self._sslobj.do_handshake()
ConnectionResetError: [WinError 10054] 远程主机强迫关闭了一个现有的连接。

During handling of the above exception, another exception occurred:

Traceback (most recent call last):
  File "E:\WorkSpace\PythonWorkSpace\shopping_platform\venv\lib\site-packages\requests\adapters.py", line 486, in send
    resp = conn.urlopen(
  File "E:\WorkSpace\PythonWorkSpace\shopping_platform\venv\lib\site-packages\urllib3\connectionpool.py", line 844, in urlopen
    retries = retries.increment(
  File "E:\WorkSpace\PythonWorkSpace\shopping_platform\venv\lib\site-packages\urllib3\util\retry.py", line 470, in increment
    raise reraise(type(error), error, _stacktrace)
  File "E:\WorkSpace\PythonWorkSpace\shopping_platform\venv\lib\site-packages\urllib3\util\util.py", line 38, in reraise
    raise value.with_traceback(tb)
  File "E:\WorkSpace\PythonWorkSpace\shopping_platform\venv\lib\site-packages\urllib3\connectionpool.py", line 776, in urlopen
    self._prepare_proxy(conn)
  File "E:\WorkSpace\PythonWorkSpace\shopping_platform\venv\lib\site-packages\urllib3\connectionpool.py", line 1041, in _prepare_proxy
    conn.connect()
  File "E:\WorkSpace\PythonWorkSpace\shopping_platform\venv\lib\site-packages\urllib3\connection.py", line 635, in connect
    sock_and_verified = _ssl_wrap_socket_and_match_hostname(
  File "E:\WorkSpace\PythonWorkSpace\shopping_platform\venv\lib\site-packages\urllib3\connection.py", line 774, in _ssl_wrap_socket_and_match_hostname
    ssl_sock = ssl_wrap_socket(
  File "E:\WorkSpace\PythonWorkSpace\shopping_platform\venv\lib\site-packages\urllib3\util\ssl_.py", line 459, in ssl_wrap_socket
    ssl_sock = _ssl_wrap_socket_impl(sock, context, tls_in_tls, server_hostname)
  File "E:\WorkSpace\PythonWorkSpace\shopping_platform\venv\lib\site-packages\urllib3\util\ssl_.py", line 503, in _ssl_wrap_socket_impl
    return ssl_context.wrap_socket(sock, server_hostname=server_hostname)
  File "E:\software\Python\lib\ssl.py", line 513, in wrap_socket
    return self.sslsocket_class._create(
  File "E:\software\Python\lib\ssl.py", line 1071, in _create
    self.do_handshake()
  File "E:\software\Python\lib\ssl.py", line 1342, in do_handshake
    self._sslobj.do_handshake()
urllib3.exceptions.ProtocolError: ('Connection aborted.', ConnectionResetError(10054, '远程主机强迫关闭了一个现有的连接。', None, 10054, None))

During handling of the above exception, another exception occurred:

Traceback (most recent call last):
  File "E:\WorkSpace\PythonWorkSpace\shopping_platform\venv\lib\site-packages\django\core\handlers\exception.py", line 55, in inner
    response = get_response(request)
  File "E:\WorkSpace\PythonWorkSpace\shopping_platform\venv\lib\site-packages\django\core\handlers\base.py", line 197, in _get_response
    response = wrapped_callback(request, *callback_args, **callback_kwargs)
  File "E:\WorkSpace\PythonWorkSpace\shopping_platform\venv\lib\site-packages\django\views\decorators\csrf.py", line 56, in wrapper_view
    return view_func(*args, **kwargs)
  File "E:\WorkSpace\PythonWorkSpace\shopping_platform\venv\lib\site-packages\django\views\generic\base.py", line 104, in view
    return self.dispatch(request, *args, **kwargs)
  File "E:\WorkSpace\PythonWorkSpace\shopping_platform\venv\lib\site-packages\rest_framework\views.py", line 509, in dispatch
    response = self.handle_exception(exc)
  File "E:\WorkSpace\PythonWorkSpace\shopping_platform\venv\lib\site-packages\rest_framework\views.py", line 469, in handle_exception
    self.raise_uncaught_exception(exc)
  File "E:\WorkSpace\PythonWorkSpace\shopping_platform\venv\lib\site-packages\rest_framework\views.py", line 480, in raise_uncaught_exception
    raise exc
  File "E:\WorkSpace\PythonWorkSpace\shopping_platform\venv\lib\site-packages\rest_framework\views.py", line 506, in dispatch
    response = handler(request, *args, **kwargs)
  File "E:\WorkSpace\PythonWorkSpace\shopping_platform\customers\views.py", line 52, in post
    result = requests.post(url, data=body, headers=headers)
  File "E:\WorkSpace\PythonWorkSpace\shopping_platform\venv\lib\site-packages\requests\api.py", line 115, in post
    return request("post", url, data=data, json=json, **kwargs)
  File "E:\WorkSpace\PythonWorkSpace\shopping_platform\venv\lib\site-packages\requests\api.py", line 59, in request
    return session.request(method=method, url=url, **kwargs)
  File "E:\WorkSpace\PythonWorkSpace\shopping_platform\venv\lib\site-packages\requests\sessions.py", line 589, in request
    resp = self.send(prep, **send_kwargs)
  File "E:\WorkSpace\PythonWorkSpace\shopping_platform\venv\lib\site-packages\requests\sessions.py", line 703, in send
    r = adapter.send(request, **kwargs)
  File "E:\WorkSpace\PythonWorkSpace\shopping_platform\venv\lib\site-packages\requests\adapters.py", line 501, in send
    raise ConnectionError(err, request=request)
requests.exceptions.ConnectionError: ('Connection aborted.', ConnectionResetError(10054, '远程主机强迫关闭了一个现有的连接。', None, 10054, None))
30/May/2023 11:24:09 [Thread-1 (process_request_thread):8580] [django.request:241] [ERROR]- Internal Server Error: /shop/api/v1/customers/
Traceback (most recent call last):
  File "E:\WorkSpace\PythonWorkSpace\shopping_platform\venv\lib\site-packages\django\core\handlers\exception.py", line 55, in inner
    response = get_response(request)
  File "E:\WorkSpace\PythonWorkSpace\shopping_platform\venv\lib\site-packages\django\core\handlers\base.py", line 197, in _get_response
    response = wrapped_callback(request, *callback_args, **callback_kwargs)
  File "E:\WorkSpace\PythonWorkSpace\shopping_platform\venv\lib\site-packages\django\views\decorators\csrf.py", line 56, in wrapper_view
    return view_func(*args, **kwargs)
  File "E:\WorkSpace\PythonWorkSpace\shopping_platform\venv\lib\site-packages\django\views\generic\base.py", line 104, in view
    return self.dispatch(request, *args, **kwargs)
  File "E:\WorkSpace\PythonWorkSpace\shopping_platform\venv\lib\site-packages\rest_framework\views.py", line 509, in dispatch
    response = self.handle_exception(exc)
  File "E:\WorkSpace\PythonWorkSpace\shopping_platform\venv\lib\site-packages\rest_framework\views.py", line 469, in handle_exception
    self.raise_uncaught_exception(exc)
  File "E:\WorkSpace\PythonWorkSpace\shopping_platform\venv\lib\site-packages\rest_framework\views.py", line 480, in raise_uncaught_exception
    raise exc
  File "E:\WorkSpace\PythonWorkSpace\shopping_platform\venv\lib\site-packages\rest_framework\views.py", line 506, in dispatch
    response = handler(request, *args, **kwargs)
  File "E:\WorkSpace\PythonWorkSpace\shopping_platform\customers\views.py", line 57, in post
    first_name=customer_data['first_name'],
TypeError: list indices must be integers or slices, not str
